Workbook

Sheet README
A1: Домашнее задание №1. Расчет Baseline
A2: 1. Краткий бизнес-контекст
A4: Avito Товары «Мода и одежда» - раздел платформы Авито, который представляет собой площадку для купли-продажи одежды, обуви и аксессуаров
A6: Segment | B6: Needs | C6: Value proposition
A7: Практичные покупатели C2C (25-40 лет, жители средних городов (> 100 тыс население)) | B7: - Экономия денег - Уверенность в качестве - Быстрый поиск - Безопасные сделки | C7: Авито "Мода и одежда" - удобная площадка для выгодных покупок б/у вещей. С помощью удобного поиска, фильтров, рейтингов продавцов, безопасных сделок и доставки, вы быстро и безопасно найдёте желаемое.
A8: Премиум/люкс энтузиасты и реселлеры C2C (18-30 лет, жители крупных городов) | B8: - Уникальность и стиль - Подлинность брендов - Вдохновение и тренды | C8: Авито "Мода и одежда" - ваш проводник в мир уникальной моды. Премиальная витрина и фильтр "Оригинал" - удобный поиск винтажных и дизайнерских вещей, а проверка подлинности защитит от подделок
A9: Частные продавцы C2C (20-45 лет, вся Россия) | B9: - Быстрая монетизация - Минимум усилий на продажу - Постоянный поток покупателей | C9: Авито "Мода и одежда" - удобная площадка для продажи вещей. Простой интерфейс, инструменты продвижения и алгоритмы постоянного потока покупателей минимизируют усилия и обеспечивают доход
A11: Ключевые проблемы, которые решает продукт:
A12: · Экономия бюджета и доступность брендов
A13: · Монетизация ненужных вещей и расхламление
A14: · Поиск уникальных и дефицитных вещей
A15: · Безопасные сделки
A16: · Географических ограничения
A18: Метрики успеха:
A19: NSM = Orders Fulfilled
A20: Key Driver: GMV
A21: Monetization: Total Revenue
A23: 2. Выбор метода расчета baseline
A24: Выбранный метод: Bottom-Up, Категория Fashion на Авито устоявшийся бизнес с накопленной статистикой. У нас есть доступные макро-метрики, что позволяет моделировать выручку от поведения реального пользователя, а не от абстрактной доли рынка
... A60: Все данные подтверждены источниками 2024-2026 (Vinted/CLOSO, eBay Q4 2024, Shopify, Коммерсант, VWO).

Sheet Assumptions
A3: TAM (Fashion Market) mln | B3: 180000 | C3: Вкладка «Данные для ДЗ №1»
A4: SAM Share % | B4: 0.45 | C4: Вкладка «Данные для ДЗ №1»
A5: SAM mln rub year | B5: =B3*B4 -> 81000 | C5: Посчитала основываясь на TAM и коэффициенте, оба значения были на вкладке «Данные для ДЗ №1»
A6: SAM mln rub month | B6: =B5/12 -> 6750 | C6: Разделила предыдущее значение для получения месяца
A7: SOM % | B7: 0.3 | C7: Вкладка «Данные для ДЗ №1»
A8: SOM mln rub year | B8: =B5*B7 -> 24300 | C8: Посчитала основываясь на SAM и коэффициенте (был на вкладке «Данные для ДЗ №1»)
A9: SOM mln rub month | B9: =B8/12 -> 2025 | C9: Разделила предыдущее значение для получения месяца
A10: Инфляция (YoY) | B10: 0.15 | C10: Инфляция в fashion ~10% YoY (обувь +59% за 3 года, одежда +36%). Источник: https://www.kommersant.ru/doc/8180662
A11: Инфляция (month) | B11: =POWER((1+B10),(1/12))-1 -> 0.011714917 | C11: Посчитано на основе предыдущего значения
A12: Base MAU (Fashion) | B12: 9 | C12: Вкладка «Данные для ДЗ №1»
A13: Organic Traffic Growth (YoY) | B13: 0.05 | C13: Стратегия Scale
A14: Organic Traffic Growth (month) | B14: =POWER((1+B13),(1/12))-1 -> 0.0040741238 | C14: Посчитано на основе предыдущего значения
A15: CR (View → All Orders) | B15: 0.03 | C15: Вкладка «Данные для ДЗ №2»
A16: Delivery Share | B16: 0.37 | C16: Экспертное допущение (на основе данных о росте TRX)
A17: Return Rate | B17: 0.1 | C17: Бенчмарк fashion e-com
A18: AOV | B18: 2500 | C18: Рыночный бенчмарк C2C
A19: Take Rate | B19: 0.07 | C19: Вкладка «Данные для ДЗ №2» (диапазон 5-10%)
A20: Сезонность январь | B20: 0.9 | C20: Спад после праздничного пика. Продажи падают на 10–25% по сравнению с декабрём https://nsk.dk.ru/news/237219082
A21: Сезонность февраль | B21: 0.9
A22: Сезонность март | B22: 1.05 | C22: Начало весеннего роста. Покупательская активность увеличивается на 15% по сравнению с февралем https://nsk.dk.ru/news/237219082
A23: Сезонность апрель | B23: 1.1 | C23: Продолжение весеннего спроса. Распродаются зимние коллекции (скидки до 50-70%) и покупаются демисезонные вещи https://newsland.com/post/7842940-rossiyanam-raskryli-sekrety-kogda-i-chto-luchshe-pokupat-na-rasprodazhah
A24: Сезонность май | B24: 0.8 | C24: Небольшой спад перед летним сезоном. Потребители готовятся к лету, но пик летних покупок ещё впереди https://partner.market.yandex.ru/chtojournal/kalendar_sezonnosti/#odezhda
A25: Сезонность июнь | B25: 1 | C25: Начало летнего пика. На летний период (июнь-август) приходится 36% всех платежей в магазинах одежды . Активно покупаются футболки, майки, летняя одежда https://www.rsb.ru/press-center/publications/2023/230923/
A26: Сезонность июль | B26: 0.9 | C26: Летний сезон продолжается, но возможен небольшой спад из-за отпусков. В некоторых каналах продаж (рынки) июль может быть очень низким
A27: Сезонность август | B27: 0.9 | C27: https://focus.bi/blog/tpost/bc6sbcayv1-itogi-pervogo-polugodiya-fashion-riteila
A28: Сезонность сентябрь | B28: 1.15 | C28: Пик осеннего сезона. Посещаемость ТЦ растёт на 20% по сравнению с августом . Начало активных продаж верхней одежды . Многие источники указывают сентябрь как один из самых высоких месяцев в году https://www.hzwincome.com/ru/news/peak-season-analysis-for-jackets/
A29: Сезонность октябрь | B29: 1 | C29: Высокий сезон продолжается. Пик продаж верхней одежды (пальто, куртки) https://www.hzwincome.com/ru/news/peak-season-analysis-for-jackets/
A30: Сезонность ноябрь | B30: 1.1 | C30: Высокий сезон, подогретый распродажами ("Черная пятница"). Пик продаж свитеров, худи, зимней одежды
A31: Сезонность декабрь | B31: 1.2 | C31: Главный пик года. Максимальный спрос на подарочные категории, вечернюю одежду, новогодний декор. На декабрь приходится до четверти годовых продаж в некоторых категориях . В некоторых каналах (рынки) декабрь может уступать августу или сентябрю, но в целом это месяц максимальной потребительской активности
A33: --- ГИПОТЕЗА 1: Bundle Offers ---
A34: H1: Base Items per Order | B34: 1 | C34: Среднее кол-во товаров в заказе на C2C fashion = 1.0
A35: H1: Items/Order uplift | B35: 0.15 | C35: Vinted: avg бандл = 3.5 товара (CLOSO 2024). Adoption ~20%, дисконт 0.5 за non-kids → +15%. Источник: https://closo.co/blogs/blog/vinted-reselling-the-zero-fee-loophole-that-changed-my-business
A36: H1: AOV uplift (вспомогательная) | B36: 0.1 | C36: Вторичная метрика. +10% AOV как следствие роста items/order (дисконт от 20%).
A37: H1: Retention decay | B37: -0.01 | C37: Умеренный эффект: -1% retention. Бандлы одновременно насыщают спрос (негатив) и повышают удовлетворённость/лояльность (позитив, частично компенсируя). Fashion ecom retention = 31% (Shopify 2025). Источник: https://www.shopify.com/blog/average-customer-retention-rate-by-industry
A38: H1: Cannibalization (orders) | B38: 0.97 | C38: Обоснование: из 20% бандл-заказов лишь ~15% реально замещают 2 отдельных заказа (остальные 85% — это доп. товар, который без бандла не купили бы). Итого: 20% × 15% = 3% снижение транзакций → коэфф 0.97. Бенчмарк: на Vinted бандлы увеличивают GMV per user, не снижая кол-во сессий.
A40: --- ГИПОТЕЗА 2: CPA Promotion ---
A41: H2: Current promo adoption | B41: 0.15 | C41: Доля продавцов с платным продвижением. eBay ~50% (4.4M, Q3 2025). Avito ниже. Источник: https://electroiq.com/stats/ebay-statistics/
A42: H2: Target promo adoption | B42: 0.35 | C42: CPA снижает порог входа → 35% (x2.3 от 15%). Источник: https://electroiq.com/stats/ebay-statistics/
A43: H2: Revenue/seller uplift | B43: 0.25 | C43: eBay Promoted Listings: +25% продаж. Источник: https://www.frooition.com/ebay-promoted-listings/
A44: H2: Take Rate uplift | B44: 0.07 | C44: Расчёт: (0.35-0.15)×5%/7% ≈ +7%. eBay: 2.4% GMV penetration (Q1 2025). Источник: https://investors.ebayinc.com/investor-news/press-release-details/2025/eBay-Inc.-Reports-Fourth-Quarter-and-Full-Year-2024-Results/
...

Sheet Hypotheses
A1: ДЗ №2. Гипотезы роста и учёт каннибализации
A2: Гипотеза | B2: Фокусная метрика | C2: uplift | H2: % раскатки | M2: Источник / обоснование | N2: Метод проверки | O2: Риск каннибализации | P2: Доп. метрики влияния
C3: 2026 | D3: 2027 | E3: 2028 | F3: 2029 | G3: 2030 | H3: 2026 | I3: 2027 | J3: 2028 | K3: 2029 | L3: 2030
A4: Bundle Offers (Покупка комплектом) Если мы дадим покупателю возможность собирать «Комплекты» из нескольких вещей одного продавца в одну посылку, то кол-во товаров в заказе (Items per Order) вырастет на 15% у охваченных пользователей. AOV вырастет на ~10% как вспомогательная метрика. | B4: Items per Order (вспомогательная: AOV) | C4: 0.15 | D4: 0.15 | E4: 0.15 | F4: =0.15*(1-Assumptions!B51) -> 0.135 | G4: =0.15*(1-Assumptions!B51)^2 -> 0.1215 | H4: 0.1 | I4: 0.5 | J4: 1 | K4: 1 | L4: 1 | M4: Vinted: до 35% сделок — бандлы, avg бандл = 3.5 товара (CLOSO, 2024). Дисконт 0.5x за перенос с детской одежды на весь Fashion. Расчёт: 20% adoption × (2.5-1)/1 × 0.5 = +15%. eBay bundle data, fashion ecom retention = 31% (Shopify, 2025). Источники: https://closo.co/blogs/blog/vinted-reselling-the-zero-fee-loophole-that-changed-my-business https://www.shopify.com/blog/average-customer-retention-rate-by-industry | N4: A/B-тест в категориях «Женская одежда» + «Детская одежда» (2 категории для снижения bias). Длительность: 6 недель. Выборка: 50 000 пользователей на группу (MDE=5%, α=0.05, power=0.80). Критерий успеха: Items per Order ≥ +10% при p < 0.05. Holdout-группа 5% для оценки retention. | O4: Каннибализация H1: 1. Снижение числа транзакций (коэфф 0.97) Из 20% бандл-заказов только 15% реально замещают 2 отдельных заказа. Остальные 85% — доп. товар, который без бандла не купили бы. Расчёт: 20% × 15% = 3% → коэфф 0.97. Бенчмарк: на Vinted бандлы увеличивают GMV per user, не снижая число сессий (CLOSO, 2024). 2. Снижение Retention (-1% MAU) Покупатель набирает комплект на сезон и реже возвращается. Частично компенсируется ростом лояльности от удобства механики. Бенчмарк: fashion ecom retention 31% (Shopify, 2025). Итого нетто: -3% orders, +12% AOV = положительный GMV 1. Снижение числа транзакций (коэфф 0.97) Механизм: 2 отдельных заказа схлопываются в 1 бандл. Оценка: bundle adoption = 20% заказов. Из них только 15% реально замещают отдельные покупки (остальные 85% — доп. товар, который покупатель без механики бандла не добавил бы). Расчёт: 20% × 15% = 3% снижение транзакций → коэфф 0.97. Бенчмарк: на Vinted бандлы увеличивают GMV per user, а не каннибализируют транзакции. 2. Снижение Retention (коэфф -1%) Механизм: покупатель закупает комплект на сезон и реже возвращается. Оценка: -1% от MAU bundle-покупателей (умеренно, т.к. механика бандлов также повышает лояльность — удовлетворённость покупкой частично компенсирует насыщение спроса). Бенчмарк: fashion ecom retention = 31% (Shopify, 2025). 3. Почему эффект умеренный: — Бандлы привлекают НОВЫЕ покупки (доп. товар), а не только замещают старые — Экономия на доставке стимулирует повторные визиты — Удовлетворённость комплектом повышает NPS и retention Итого влияние на Revenue: -3% orders × +12% AOV = +9% GMV (нетто положительный) | P4: • Retention Rate: -3% (насыщение спроса) • AOV: +10% (вспомогательная) • Затухание: -10%/год с 2029 • Синергия с H2: +2%
A5: AI Recommendations (Персонализированные рекомендации) Если мы внедрим AI-рекомендации товаров (персонализированная витрина на основе истории просмотров и покупок), то GMV per buyer вырастет на 15%, а retention улучшится на 5%, так как пользователи будут чаще находить релевантные товары и возвращаться на платформу. Побочный эффект: небольшое снижение органического поиска (-3% GMV от каннибализации) и VAS-расходов продавцов (-2%), так как AI-буст частично заменяет платное продвижение. | B5: GMV per buyer (+15%) (вспомогательные: Retention +5%, ARPU Total) | C5: =Assumptions!$B$58 -> 0.15 | D5: =Assumptions!$B$58 -> 0.15 | E5: =Assumptions!$B$58 -> 0.15 | F5: =Assumptions!$B$59 -> 0.135 | G5: =Assumptions!$B$60 -> 0.1215 | H5: 0.15 | I5: 0.6 | J5: 1 | K5: 1 | L5: 1 | M5: Amazon: персонализация даёт +15% GMV (McKinsey, 2024). Netflix: AI-рекомендации снижают churn на 5%. Бенчмарк fashion C2C: Vinted AI-рекомендации +12-18% conversion (2024). Organic search cannib 3%: перераспределение трафика с поиска на рекомендации. VAS cannib 2%: продавцы с AI-буст снижают расходы на платное продвижение. | N5: A/B-тест на 20% аудитории (treatment — персонализированная главная страница). Длительность: 8 недель. Критерий успеха: GMV per buyer ≥ +10% при p < 0.05. Мониторинг: retention cohort D30, VAS revenue delta, органический поиск CTR. | O5: Каннибализация H2: 1. Органический поиск: -3% GMV (пользователи переходят с поиска на рекомендации → меньше сессий через SEO-каналы) 2. VAS Revenue: -2% (AI-продвижение частично заменяет платное, снижает стимул продавца покупать VAS) Итого Net GMV uplift: +15% × rollout × (1 - 3% cannib) ≈ +14.5% | P5: • Retention Rate: +5% (AI повышает релевантность) • VAS Revenue: -2% каннибализация • Органический поиск: -3% GMV • Затухание: -10%/год с 2029 (конкуренты копируют, эффект снижается) • Синергия с H1: +2% (бандлы в рекомендациях усиливают эффект)
A7: Взаимное влияние гипотез | B7: Синергия: +2% (AI-рекомендации ↑показывают бандлы → усиливают H1 Items per Order). Затухание: -10%/год после полной раскатки (с 2029). Полная раскатка H1 к 2028, H2 AI Reco к 2028 (раскатка 15% → 60% → 100%).

Sheet Traction model
T1: fact | U1: plan
C2: 2026 | D2: =C2 -> 2026 | E2: =D2 -> 2026 | F2: =E2 -> 2026 | G2: =F2 -> 2026 | H2: =G2 -> 2026 | I2: =H2 -> 2026 | J2: =I2 -> 2026 | K2: =J2 -> 2026 | ... N2: =M2 -> 2026 | O2: =C2+1 -> 2027 | P2: =O2 -> 2027 | Q2: =P2 -> 2027 | R2: =Q2 -> 2027 | S2: =R2 -> 2027 | T2: =S2 -> 2027 | U2: =T2 -> 2027 | V2: =U2 -> 2027 | W2: =V2 -> 2027 | ... Z2: =Y2 -> 2027 | AA2: =O2+1 -> 2028 | AB2: =AA2 -> 2028 | AC2: =AB2 -> 2028 | AD2: =AC2 -> 2028 | AE2: =AD2 -> 2028 | AF2: =AE2 -> 2028 | AG2: =AF2 -> 2028 | AH2: =AG2 -> 2028 | AI2: =AH2 -> 2028 | ... AL2: =AK2 -> 2028 | AM2: =AA2+1 -> 2029 | AN2: =AM2 -> 2029 | AO2: =AN2 -> 2029 | AP2: =AO2 -> 2029 | AQ2: =AP2 -> 2029 | AR2: =AQ2 -> 2029 | AS2: =AR2 -> 2029 | AT2: =AS2 -> 2029 | AU2: =AT2 -> 2029 | ... AX2: =AW2 -> 2029 | AY2: =AM2+1 -> 2030 | AZ2: =AY2 -> 2030 | BA2: =AZ2 -> 2030 | BB2: =BA2 -> 2030 | BC2: =BB2 -> 2030 | BD2: =BC2 -> 2030 | BE2: =BD2 -> 2030 | BF2: =BE2 -> 2030 | BG2: =BF2 -> 2030 | ... BJ2: =BI2 -> 2030 | BL2: 2026 | BM2: 2027 | BN2: 2028 | BO2: 2029 | BP2: 2030 | BQ2: 5Y
A3: Parameter | B3: Unit | C3: 31 | D3: 28 | E3: 31 | F3: 30 | G3: 31 | H3: 30 | I3: 31 | J3: 31 | K3: 30 | L3: 31 | M3: 30 | N3: 31 | O3: 31 | P3: 28 | Q3: 31 | R3: 30 | S3: 31 | T3: 30 | U3: 31 | V3: 31 | W3: 30 | X3: 31 | Y3: 30 | Z3: 31 | AA3: 31 | AB3: 28 | AC3: 31 | AD3: 30 | AE3: 31 | AF3: 30 | AG3: 31 | AH3: 31 | AI3: 30 | AJ3: 31 | AK3: 30 | AL3: 31 | AM3: 31 | AN3: 28 | AO3: 31 | AP3: 30 | AQ3: 31 | AR3: 30 | AS3: 31 | AT3: 31 | AU3: 30 | AV3: 31 | AW3: 30 | AX3: 31 | AY3: 31 | AZ3: 29 | BA3: 31 | BB3: 30 | BC3: 31 | BD3: 30 | BE3: 31 | BF3: 31 | BG3: 30 | BH3: 31 | BI3: 30 | BJ3: 31
C4: Jan | D4: Feb | E4: Mar | F4: Apr | G4: May | H4: Jun | I4: Jul | J4: Aug | K4: Sep | L4: Oct | M4: Nov | N4: Dec | O4: Jan | P4: Feb | Q4: Mar | R4: Apr | S4: May | T4: Jun | U4: Jul | V4: Aug | W4: Sep | X4: Oct | Y4: Nov | Z4: Dec | AA4: Jan | AB4: Feb | AC4: Mar | AD4: Apr | AE4: May | AF4: Jun | AG4: Jul | AH4: Aug | AI4: Sep | AJ4: Oct | AK4: Nov | AL4: Dec | AM4: Jan | AN4: Feb | AO4: Mar | AP4: Apr | AQ4: May | AR4: Jun | AS4: Jul | AT4: Aug | AU4: Sep | AV4: Oct | AW4: Nov | AX4: Dec | AY4: Jan | AZ4: Feb | BA4: Mar | BB4: Apr | BC4: May | BD4: Jun | BE4: Jul | BF4: Aug | BG4: Sep | BH4: Oct | BI4: Nov | BJ4: Dec
A6: MARKET ASSUMPTIONS
A8: Total market size (SAM) | B8: mln rub | C8: =Assumptions!B6*C13 -> 6075 | D8: =C8/C13*D13 -> 6075 | E8: =D8/D13*E13 -> 7087.5 | F8: =E8/E13*F13 -> 7425 | G8: =F8/F13*G13 -> 5400 | H8: =G8/G13*H13 -> 6750 | I8: =H8/H13*I13 -> 6075 | J8: =I8/I13*J13 -> 6075 | K8: =J8/J13*K13 -> 7762.5 | ... BJ8: =BI8/BI13*BJ13 -> 8100 | BL8: =SUMIF($C$2:$BJ$2,BL$2,$C8:$BJ8) -> 81000 | BM8: =SUMIF($C$2:$BJ$2,BM2,$C8:$BJ8) -> 81000 | BN8: =SUMIF($C$2:$BJ$2,BN2,$C8:$BJ8) -> 81000 | BO8: =SUMIF($C$2:$BJ$2,BO2,$C8:$BJ8) -> 81000 | BP8: =SUMIF($C$2:$BJ$2,BP2,$C8:$BJ8) -> 81000 | BQ8: =BL8+BM8+BN8+BO8+BP8 -> 405000
A9: % change YoY | B9: %
A10: SOM | B10: mln rub | C10: =Assumptions!B9*C13 -> 1822.5 | D10: =C10/C13*D13 -> 1822.5 | E10: =D10/D13*E13 -> 2126.25 | F10: =E10/E13*F13 -> 2227.5 | G10: =F10/F13*G13 -> 1620 | H10: =G10/G13*H13 -> 2025 | I10: =H10/H13*I13 -> 1822.5 | J10: =I10/I13*J13 -> 1822.5 | K10: =J10/J13*K13 -> 2328.75 | ... BJ10: =BI10/BI13*BJ13 -> 2430 | BL10: =AVERAGEIFS($C10:$BJ10,$C$2:$BJ$2,BL$2) -> 2025 | BM10: =AVERAGEIFS($C10:$BJ10,$C2:$BJ2,BM2) -> 2025 | BN10: =AVERAGEIFS($C10:$BJ10,$C2:$BJ2,BN2) -> 2025 | BO10: =AVERAGEIFS($C10:$BJ10,$C2:$BJ2,BO2) -> 2025 | BP10: =AVERAGEIFS($C10:$BJ10,$C2:$BJ2,BP2) -> 2025 | BQ10: =AVERAGE(BL10:BP10) -> 2025
A11: % change YoY | B11: %
A13: Seasonal coefficient | B13: % | C13: =Assumptions!$B$20 -> 0.9 | D13: =Assumptions!$B$21 -> 0.9 | E13: =Assumptions!$B$22 -> 1.05 | F13: =Assumptions!$B$23 -> 1.1 | G13: =Assumptions!$B$24 -> 0.8 | H13: =Assumptions!$B$25 -> 1 | I13: =Assumptions!$B$26 -> 0.9 | J13: =Assumptions!$B$27 -> 0.9 | K13: =Assumptions!$B$28 -> 1.15 | L13: =Assumptions!$B$29 -> 1 | M13: =Assumptions!$B$30 -> 1.1 | N13: =Assumptions!$B$31 -> 1.2 | O13: =Assumptions!$B$20 -> 0.9 | P13: =Assumptions!$B$21 -> 0.9 | Q13: =Assumptions!$B$22 -> 1.05 | R13: =Assumptions!$B$23 -> 1.1 | S13: =Assumptions!$B$24 -> 0.8 | T13: =Assumptions!$B$25 -> 1 | U13: =Assumptions!$B$26 -> 0.9 | V13: =Assumptions!$B$27 -> 0.9 | W13: =Assumptions!$B$28 -> 1.15 | X13: =Assumptions!$B$29 -> 1 | Y13: =Assumptions!$B$30 -> 1.1 | Z13: =Assumptions!$B$31 -> 1.2 | AA13: =Assumptions!$B$20 -> 0.9 | AB13: =Assumptions!$B$21 -> 0.9 | AC13: =Assumptions!$B$22 -> 1.05 | AD13: =Assumptions!$B$23 -> 1.1 | AE13: =Assumptions!$B$24 -> 0.8 | AF13: =Assumptions!$B$25 -> 1 | AG13: =Assumptions!$B$26 -> 0.9 | AH13: =Assumptions!$B$27 -> 0.9 | AI13: =Assumptions!$B$28 -> 1.15 | AJ13: =Assumptions!$B$29 -> 1 | AK13: =Assumptions!$B$30 -> 1.1 | AL13: =Assumptions!$B$31 -> 1.2 | AM13: =Assumptions!$B$20 -> 0.9 | AN13: =Assumptions!$B$21 -> 0.9 | AO13: =Assumptions!$B$22 -> 1.05 | AP13: =Assumptions!$B$23 -> 1.1 | AQ13: =Assumptions!$B$24 -> 0.8 | AR13: =Assumptions!$B$25 -> 1 | AS13: =Assumptions!$B$26 -> 0.9 | AT13: =Assumptions!$B$27 -> 0.9 | AU13: =Assumptions!$B$28 -> 1.15 | AV13: =Assumptions!$B$29 -> 1 | AW13: =Assumptions!$B$30 -> 1.1 | AX13: =Assumptions!$B$31 -> 1.2 | AY13: =Assumptions!$B$20 -> 0.9 | AZ13: =Assumptions!$B$21 -> 0.9 | BA13: =Assumptions!$B$22 -> 1.05 | BB13: =Assumptions!$B$23 -> 1.1 | BC13: =Assumptions!$B$24 -> 0.8 | BD13: =Assumptions!$B$25 -> 1 | BE13: =Assumptions!$B$26 -> 0.9 | BF13: =Assumptions!$B$27 -> 0.9 | BG13: =Assumptions!$B$28 -> 1.15 | BH13: =Assumptions!$B$29 -> 1 | BI13: =Assumptions!$B$30 -> 1.1 | BJ13: =Assumptions!$B$31 -> 1.2
A15: BASELINE
A17: Monthly Active User | B17: mln | C17: =Assumptions!$B$12*C13 -> 8.1 | D17: =C17/C13*(Assumptions!$B$14+1)*D13 -> 8.1330004 | E17: =D17/D13*(Assumptions!$B$14+1)*E13 -> 9.5271578 | F17: =E17/E13*(Assumptions!$B$14+1)*F13 -> 10.021495 | G17: =F17/F13*(Assumptions!$B$14+1)*G13 -> 7.3180538 | H17: =G17/G13*(Assumptions!$B$14+1)*H13 -> 9.1848355 | I17: =H17/H13*(Assumptions!$B$14+1)*I13 -> 8.3000301 | J17: =I17/I13*(Assumptions!$B$14+1)*J13 -> 8.3338455 | K17: =J17/J13*(Assumptions!$B$14+1)*K13 -> 10.692187 | ... BJ17: =BI17/BI13*(Assumptions!$B$14+1)*BJ13 -> 13.727912 | BL17: =AVERAGEIFS($C17:$BJ17,$C$2:$BJ$2,BL$2) -> 9.2125699 | BM17: =AVERAGEIFS($C17:$BJ17,$C$2:$BJ$2,BM$2) -> 9.6731984 | BN17: =AVERAGEIFS($C17:$BJ17,$C$2:$BJ$2,BN$2) -> 10.156858 | BO17: =AVERAGEIFS($C17:$BJ17,$C$2:$BJ$2,BO$2) -> 10.664701 | BP17: =AVERAGEIFS($C17:$BJ17,$C$2:$BJ$2,BP$2) -> 11.197936 | BQ17: =AVERAGE(BL17:BP17) -> 10.181053
A19: AOV | B19: Rub | C19: =Assumptions!$B$18 -> 2500 | D19: =C19*(Assumptions!$B$11+1) -> 2529.2873 | E19: =D19*(Assumptions!$B$11+1) -> 2558.9177 | F19: =E19*(Assumptions!$B$11+1) -> 2588.8952 | G19: =F19*(Assumptions!$B$11+1) -> 2619.2239 | H19: =G19*(Assumptions!$B$11+1) -> 2649.9079 | I19: =H19*(Assumptions!$B$11+1) -> 2680.9513 | J19: =I19*(Assumptions!$B$11+1) -> 2712.3584 | K19: =J19*(Assumptions!$B$11+1) -> 2744.1335 | ... BJ19: =BI19*(Assumptions!$B$11+1) -> 4970.1679 | BL19: =AVERAGEIFS($C19:$BJ19,$C$2:$BJ$2,BL$2) -> 2667.5392 | BM19: =AVERAGEIFS($C19:$BJ19,$C$2:$BJ$2,BM$2) -> 3067.6701 | BN19: =AVERAGEIFS($C19:$BJ19,$C$2:$BJ$2,BN$2) -> 3527.8206 | BO19: =AVERAGEIFS($C19:$BJ19,$C$2:$BJ$2,BO$2) -> 4056.9937 | BP19: =AVERAGEIFS($C19:$BJ19,$C$2:$BJ$2,BP$2) -> 4665.5427 | BQ19: =AVERAGE(BL19,BM19,BN19,BO19,BP19) -> 3597.1132
A21: CR MAU -> Order placed | B21: % | C21: =Assumptions!$B$15 -> 0.03 | D21: =C21 -> 0.03 | E21: =D21 -> 0.03 | F21: =E21 -> 0.03 | G21: =F21 -> 0.03 | H21: =G21 -> 0.03 | I21: =H21 -> 0.03 | J21: =I21 -> 0.03 | K21: =J21 -> 0.03 | ... BJ21: =BI21 -> 0.03 | BL21: =AVERAGEIFS($C21:$BJ21,$C$2:$BJ$2,BL$2) -> 0.03 | BM21: =AVERAGEIFS($C21:$BJ21,$C$2:$BJ$2,BM$2) -> 0.03 | BN21: =AVERAGEIFS($C21:$BJ21,$C$2:$BJ$2,BN$2) -> 0.03 | BO21: =AVERAGEIFS($C21:$BJ21,$C$2:$BJ$2,BO$2) -> 0.03 | BP21: =AVERAGEIFS($C21:$BJ21,$C$2:$BJ$2,BP$2) -> 0.03 | BQ21: =AVERAGE(BL21:BP21) -> 0.03
A23: Total Orders | B23: count | C23: =C17*1000000*C21 -> 243000 | D23: =D17*1000000*D21 -> 243990.01 | E23: =E17*1000000*E21 -> 285814.73 | F23: =F17*1000000*F21 -> 300644.85 | G23: =G17*1000000*G21 -> 219541.61 | H23: =H17*1000000*H21 -> 275545.07 | I23: =I17*1000000*I21 -> 249000.9 | J23: =J17*1000000*J21 -> 250015.36 | ... BJ23: =BJ17*1000000*BJ21 -> 411837.35 | BL23: =SUMIF($C$2:$BJ$2,BL$2,$C23:$BJ23) -> 3316525.2 | BM23: =SUMIF($C$2:$BJ$2,BM$2,$C23:$BJ23) -> 3482351.4 | BN23: =SUMIF($C$2:$BJ$2,BN$2,$C23:$BJ23) -> 3656469 | BO23: =SUMIF($C$2:$BJ$2,BO$2,$C23:$BJ23) -> 3839292.5 | BP23: =SUMIF($C$2:$BJ$2,BP$2,$C23:$BJ23) -> 4031257.1 | BQ23: =BL23+BM23+BN23+BO23+BP23 -> 18325895
A25: Orders paid | B25: count | C25: =C23*Assumptions!$B$16 -> 89910 | D25: =D23*Assumptions!$B$16 -> 90276.304 | E25: =E23*Assumptions!$B$16 -> 105751.45 | F25: =F23*Assumptions!$B$16 -> 111238.6 | G25: =G23*Assumptions!$B$16 -> 81230.397 | H25: =H23*Assumptions!$B$16 -> 101951.67 | I25: =I23*Assumptions!$B$16 -> 92130.334 | J25: =J23*Assumptions!$B$16 -> 92505.685 | ... BJ25: =BJ23*Assumptions!$B$16 -> 152379.82 | BL25: =SUMIF($C$2:$BJ$2,BL$2,$C25:$BJ25) -> 1227114.3 | BM25: =SUMIF($C$2:$BJ$2,BM$2,$C25:$BJ25) -> 1288470 | BN25: =SUMIF($C$2:$BJ$2,BN$2,$C25:$BJ25) -> 1352893.5 | BO25: =SUMIF($C$2:$BJ$2,BO$2,$C25:$BJ25) -> 1420538.2 | BP25: =SUMIF($C$2:$BJ$2,BP$2,$C25:$BJ25) -> 1491565.1 | BQ25: =BL25+BM25+BN25+BO25+BP25 -> 6780581.2
A27: Share of Canceled | B27: % | C27: =Assumptions!$B$17 -> 0.1 | D27: =$C$27 -> 0.1 | E27: =$C$27 -> 0.1 | F27: =$C$27 -> 0.1 | G27: =$C$27 -> 0.1 | H27: =$C$27 -> 0.1 | I27: =$C$27 -> 0.1 | J27: =$C$27 -> 0.1 | K27: =$C$27 -> 0.1 | ... BJ27: =$C$27 -> 0.1 | BL27: =AVERAGEIFS($C27:$BJ27,$C$2:$BJ$2,BL$2) -> 0.1 | BM27: =AVERAGEIFS($C27:$BJ27,$C$2:$BJ$2,BM$2) -> 0.1 | BN27: =AVERAGEIFS($C27:$BJ27,$C$2:$BJ$2,BN$2) -> 0.1 | BO27: =AVERAGEIFS($C27:$BJ27,$C$2:$BJ$2,BO$2) -> 0.1 | BP27: =AVERAGEIFS($C27:$BJ27,$C$2:$BJ$2,BP$2) -> 0.1 | BQ27: =AVERAGE(BL27:BP27) -> 0.1
A29: Orders Fulfilled | B29: count | C29: =C25*(1-C27) -> 80919 | D29: =D25*(1-D27) -> 81248.674 | E29: =E25*(1-E27) -> 95176.306 | F29: =F25*(1-F27) -> 100114.74 | G29: =G25*(1-G27) -> 73107.357 | H29: =H25*(1-H27) -> 91756.507 | I29: =I25*(1-I27) -> 82917.301 | J29: =J25*(1-J27) -> 83255.116 | ... BJ29: =BJ25*(1-BJ27) -> 137141.84 | BL29: =SUMIF($C$2:$BJ$2,BL$2,$C29:$BJ29) -> 1104402.9 | BM29: =SUMIF($C$2:$BJ$2,BM$2,$C29:$BJ29) -> 1159623 | BN29: =SUMIF($C$2:$BJ$2,BN$2,$C29:$BJ29) -> 1217604.2 | BO29: =SUMIF($C$2:$BJ$2,BO$2,$C29:$BJ29) -> 1278484.4 | BP29: =SUMIF($C$2:$BJ$2,BP$2,$C29:$BJ29) -> 1342408.6 | BQ29: =BL29+BM29+BN29+BO29+BP29 -> 6102523.1
A31: GMV | B31: mln Rub | C31: =C29*C19/1000000 -> 202.2975 | D31: =D29*D19/1000000 -> 205.50124 | E31: =E29*E19/1000000 -> 243.54833 | F31: =F29*F19/1000000 -> 259.18656 | G31: =G29*G19/1000000 -> 191.48454 | H31: =H29*H19/1000000 -> 243.14629 | I31: =I29*I19/1000000 -> 222.29725 | J31: =J29*J19/1000000 -> 225.81772 | ... BJ31: =BJ29*BJ19/1000000 -> 681.61795 | BL31: =SUMIF($C$2:$BJ$2,BL$2,$C31:$BJ31) -> 2955.2549 | BM31: =SUMIF($C$2:$BJ$2,BM$2,$C31:$BJ31) -> 3568.4704 | BN31: =SUMIF($C$2:$BJ$2,BN$2,$C31:$BJ31) -> 4308.9279 | BO31: =SUMIF($C$2:$BJ$2,BO$2,$C31:$BJ31) -> 5203.0305 | BP31: =SUMIF($C$2:$BJ$2,BP$2,$C31:$BJ31) -> 6282.6593 | BQ31: =BL31+BM31+BN31+BO31+BP31 -> 22318.343
A33: Take Rate | B33: % | C33: =Assumptions!$B$19 -> 0.07 | D33: =$C$33 -> 0.07 | E33: =$C$33 -> 0.07 | F33: =$C$33 -> 0.07 | G33: =$C$33 -> 0.07 | H33: =$C$33 -> 0.07 | I33: =$C$33 -> 0.07 | J33: =$C$33 -> 0.07 | K33: =$C$33 -> 0.07 | ... BJ33: =$C$33 -> 0.07 | BL33: =AVERAGEIFS($C33:$BJ33,$C$2:$BJ$2,BL$2) -> 0.07 | BM33: =AVERAGEIFS($C33:$BJ33,$C$2:$BJ$2,BM$2) -> 0.07 | BN33: =AVERAGEIFS($C33:$BJ33,$C$2:$BJ$2,BN$2) -> 0.07 | BO33: =AVERAGEIFS($C33:$BJ33,$C$2:$BJ$2,BO$2) -> 0.07 | BP33: =AVERAGEIFS($C33:$BJ33,$C$2:$BJ$2,BP$2) -> 0.07 | BQ33: =AVERAGE(BL33:BP33) -> 0.07
D34: =C34 -> 0
A35: Total Revenue | B35: mln Rub | C35: =C31*C33 -> 14.160825 | D35: =D31*D33 -> 14.385087 | E35: =E31*E33 -> 17.048383 | F35: =F31*F33 -> 18.143059 | G35: =G31*G33 -> 13.403918 | H35: =H31*H33 -> 17.02024 | I35: =I31*I33 -> 15.560807 | J35: =J31*J33 -> 15.80724 | ... BJ35: =BJ31*BJ33 -> 47.713257 | BL35: =SUMIF($C$2:$BJ$2,BL$2,$C35:$BJ35) -> 206.86785 | BM35: =SUMIF($C$2:$BJ$2,BM$2,$C35:$BJ35) -> 249.79292 | BN35: =SUMIF($C$2:$BJ$2,BN$2,$C35:$BJ35) -> 301.62496 | BO35: =SUMIF($C$2:$BJ$2,BO$2,$C35:$BJ35) -> 364.21213 | BP35: =SUMIF($C$2:$BJ$2,BP$2,$C35:$BJ35) -> 439.78615 | BQ35: =BL35+BM35+BN35+BO35+BP35 -> 1562.284
A36: VAS Revenue Baseline | B36: mln Rub | C36: =C17*Assumptions!$B$54*Assumptions!$B$55*Assumptions!$B$56 -> 901.53 | D36: =D17*Assumptions!$B$54*Assumptions!$B$55*Assumptions!$B$56 -> 905.20294 | E36: =E17*Assumptions!$B$54*Assumptions!$B$55*Assumptions!$B$56 -> 1060.3727 | F36: =F17*Assumptions!$B$54*Assumptions!$B$55*Assumptions!$B$56 -> 1115.3924 | G36: =G17*Assumptions!$B$54*Assumptions!$B$55*Assumptions!$B$56 -> 814.49938 | H36: =H17*Assumptions!$B$54*Assumptions!$B$55*Assumptions!$B$56 -> 1022.2722 | I36: =I17*Assumptions!$B$54*Assumptions!$B$55*Assumptions!$B$56 -> 923.79335 | J36: =J17*Assumptions!$B$54*Assumptions!$B$55*Assumptions!$B$56 -> 927.557 | ... BJ36: =BJ17*Assumptions!$B$54*Assumptions!$B$55*Assumptions!$B$56 -> 1527.9166 | BL36: =SUMIF($C$2:$BJ$2,BL$2,$C36:$BJ36) -> 12304.308 | BM36: =SUMIF($C$2:$BJ$2,BM$2,$C36:$BJ36) -> 12919.524 | BN36: =SUMIF($C$2:$BJ$2,BN$2,$C36:$BJ36) -> 13565.5 | BO36: =SUMIF($C$2:$BJ$2,BO$2,$C36:$BJ36) -> 14243.775 | BP36: =SUMIF($C$2:$BJ$2,BP$2,$C36:$BJ36) -> 14955.964 | BQ36: =BL36+BM36+BN36+BO36+BP36 -> 67989.071
A37: Total Revenue Baseline (Tx+VAS) | B37: mln Rub | C37: =C35+C36 -> 915.69083 | D37: =D35+D36 -> 919.58803 | E37: =E35+E36 -> 1077.421 | F37: =F35+F36 -> 1133.5355 | G37: =G35+G36 -> 827.9033 | H37: =H35+H36 -> 1039.2924 | I37: =I35+I36 -> 939.35416 | J37: =J35+J36 -> 943.36424 | ... BJ37: =BJ35+BJ36 -> 1575.6298 | BL37: =SUMIF($C$2:$BJ$2,BL$2,$C37:$BJ37) -> 12511.176 | BM37: =SUMIF($C$2:$BJ$2,BM$2,$C37:$BJ37) -> 13169.317 | BN37: =SUMIF($C$2:$BJ$2,BN$2,$C37:$BJ37) -> 13867.125 | BO37: =SUMIF($C$2:$BJ$2,BO$2,$C37:$BJ37) -> 14607.987 | BP37: =SUMIF($C$2:$BJ$2,BP$2,$C37:$BJ37) -> 15395.75 | BQ37: =BL37+BM37+BN37+BO37+BP37 -> 69551.355
A38: HYPOTHESES
A40: H1 Bundle (Items/Order uplift) | B40: % uplift | C40: =Assumptions!$B$35 -> 0.15 | D40: =Assumptions!$B$35 -> 0.15 | E40: =Assumptions!$B$35 -> 0.15 | F40: =Assumptions!$B$35 -> 0.15 | G40: =Assumptions!$B$35 -> 0.15 | H40: =Assumptions!$B$35 -> 0.15 | I40: =Assumptions!$B$35 -> 0.15 | J40: =Assumptions!$B$35 -> 0.15 | ... AL40: =Assumptions!$B$35 -> 0.15 | AM40: =Assumptions!$B$35*(1-Assumptions!$B$51)^1 -> 0.135 | AN40: =Assumptions!$B$35*(1-Assumptions!$B$51)^1 -> 0.135 | AO40: =Assumptions!$B$35*(1-Assumptions!$B$51)^1 -> 0.135 | AP40: =Assumptions!$B$35*(1-Assumptions!$B$51)^1 -> 0.135 | AQ40: =Assumptions!$B$35*(1-Assumptions!$B$51)^1 -> 0.135 | AR40: =Assumptions!$B$35*(1-Assumptions!$B$51)^1 -> 0.135 | AS40: =Assumptions!$B$35*(1-Assumptions!$B$51)^1 -> 0.135 | AT40: =Assumptions!$B$35*(1-Assumptions!$B$51)^1 -> 0.135 | ... AX40: =Assumptions!$B$35*(1-Assumptions!$B$51)^1 -> 0.135 | AY40: =Assumptions!$B$35*(1-Assumptions!$B$51)^2 -> 0.1215 | AZ40: =Assumptions!$B$35*(1-Assumptions!$B$51)^2 -> 0.1215 | BA40: =Assumptions!$B$35*(1-Assumptions!$B$51)^2 -> 0.1215 | BB40: =Assumptions!$B$35*(1-Assumptions!$B$51)^2 -> 0.1215 | BC40: =Assumptions!$B$35*(1-Assumptions!$B$51)^2 -> 0.1215 | BD40: =Assumptions!$B$35*(1-Assumptions!$B$51)^2 -> 0.1215 | BE40: =Assumptions!$B$35*(1-Assumptions!$B$51)^2 -> 0.1215 | BF40: =Assumptions!$B$35*(1-Assumptions!$B$51)^2 -> 0.1215 | ... BJ40: =Assumptions!$B$35*(1-Assumptions!$B$51)^2 -> 0.1215 | BL40: =AVERAGEIFS($C40:$BJ40,$C$2:$BJ$2,BL$2) -> 0.15 | BM40: =AVERAGEIFS($C40:$BJ40,$C$2:$BJ$2,BM$2) -> 0.15 | BN40: =AVERAGEIFS($C40:$BJ40,$C$2:$BJ$2,BN$2) -> 0.15 | BO40: =AVERAGEIFS($C40:$BJ40,$C$2:$BJ$2,BO$2) -> 0.135 | BP40: =AVERAGEIFS($C40:$BJ40,$C$2:$BJ$2,BP$2) -> 0.1215 | BQ40: =AVERAGE(BL40:BP40) -> 0.1413
A41: H1 Bundle (AOV uplift, secondary) | B41: % uplift | C41: =Assumptions!$B$36 -> 0.1 | D41: =Assumptions!$B$36 -> 0.1 | E41: =Assumptions!$B$36 -> 0.1 | F41: =Assumptions!$B$36 -> 0.1 | G41: =Assumptions!$B$36 -> 0.1 | H41: =Assumptions!$B$36 -> 0.1 | I41: =Assumptions!$B$36 -> 0.1 | J41: =Assumptions!$B$36 -> 0.1 | ... AL41: =Assumptions!$B$36 -> 0.1 | AM41: =Assumptions!$B$36*(1-Assumptions!$B$51)^1 -> 0.09 | AN41: =Assumptions!$B$36*(1-Assumptions!$B$51)^1 -> 0.09 | AO41: =Assumptions!$B$36*(1-Assumptions!$B$51)^1 -> 0.09 | AP41: =Assumptions!$B$36*(1-Assumptions!$B$51)^1 -> 0.09 | AQ41: =Assumptions!$B$36*(1-Assumptions!$B$51)^1 -> 0.09 | AR41: =Assumptions!$B$36*(1-Assumptions!$B$51)^1 -> 0.09 | AS41: =Assumptions!$B$36*(1-Assumptions!$B$51)^1 -> 0.09 | AT41: =Assumptions!$B$36*(1-Assumptions!$B$51)^1 -> 0.09 | ... AX41: =Assumptions!$B$36*(1-Assumptions!$B$51)^1 -> 0.09 | AY41: =Assumptions!$B$36*(1-Assumptions!$B$51)^2 -> 0.081 | AZ41: =Assumptions!$B$36*(1-Assumptions!$B$51)^2 -> 0.081 | BA41: =Assumptions!$B$36*(1-Assumptions!$B$51)^2 -> 0.081 | BB41: =Assumptions!$B$36*(1-Assumptions!$B$51)^2 -> 0.081 | BC41: =Assumptions!$B$36*(1-Assumptions!$B$51)^2 -> 0.081 | BD41: =Assumptions!$B$36*(1-Assumptions!$B$51)^2 -> 0.081 | BE41: =Assumptions!$B$36*(1-Assumptions!$B$51)^2 -> 0.081 | BF41: =Assumptions!$B$36*(1-Assumptions!$B$51)^2 -> 0.081 | ... BJ41: =Assumptions!$B$36*(1-Assumptions!$B$51)^2 -> 0.081 | BL41: =AVERAGEIFS($C41:$BJ41,$C$2:$BJ$2,BL$2) -> 0.1 | BM41: =AVERAGEIFS($C41:$BJ41,$C$2:$BJ$2,BM$2) -> 0.1 | BN41: =AVERAGEIFS($C41:$BJ41,$C$2:$BJ$2,BN$2) -> 0.1 | BO41: =AVERAGEIFS($C41:$BJ41,$C$2:$BJ$2,BO$2) -> 0.09 | BP41: =AVERAGEIFS($C41:$BJ41,$C$2:$BJ$2,BP$2) -> 0.081 | BQ41: =AVERAGE(BL41:BP41) -> 0.0942
A42: H1 Retention decay | B42: % | C42: =Assumptions!$B$37 -> -0.01 | D42: =Assumptions!$B$37 -> -0.01 | E42: =Assumptions!$B$37 -> -0.01 | F42: =Assumptions!$B$37 -> -0.01 | G42: =Assumptions!$B$37 -> -0.01 | H42: =Assumptions!$B$37 -> -0.01 | I42: =Assumptions!$B$37 -> -0.01 | J42: =Assumptions!$B$37 -> -0.01 | ... BJ42: =Assumptions!$B$37 -> -0.01 | BL42: =AVERAGEIFS($C42:$BJ42,$C$2:$BJ$2,BL$2) -> -0.01 | BM42: =AVERAGEIFS($C42:$BJ42,$C$2:$BJ$2,BM$2) -> -0.01 | BN42: =AVERAGEIFS($C42:$BJ42,$C$2:$BJ$2,BN$2) -> -0.01 | BO42: =AVERAGEIFS($C42:$BJ42,$C$2:$BJ$2,BO$2) -> -0.01 | BP42: =AVERAGEIFS($C42:$BJ42,$C$2:$BJ$2,BP$2) -> -0.01 | BQ42: =AVERAGE(BL42:BP42) -> -0.01
A43: H2 CPA (Take Rate uplift) | B43: % uplift | C43: =Assumptions!$B$44 -> 0.07 | D43: =Assumptions!$B$44 -> 0.07 | E43: =Assumptions!$B$44 -> 0.07 | F43: =Assumptions!$B$44 -> 0.07 | G43: =Assumptions!$B$44 -> 0.07 | H43: =Assumptions!$B$44 -> 0.07 | I43: =Assumptions!$B$44 -> 0.07 | J43: =Assumptions!$B$44 -> 0.07 | ... AL43: =Assumptions!$B$44 -> 0.07 | AM43: =Assumptions!$B$44*(1-Assumptions!$B$51)^1 -> 0.063 | AN43: =Assumptions!$B$44*(1-Assumptions!$B$51)^1 -> 0.063 | AO43: =Assumptions!$B$44*(1-Assumptions!$B$51)^1 -> 0.063 | AP43: =Assumptions!$B$44*(1-Assumptions!$B$51)^1 -> 0.063 | AQ43: =Assumptions!$B$44*(1-Assumptions!$B$51)^1 -> 0.063 | AR43: =Assumptions!$B$44*(1-Assumptions!$B$51)^1 -> 0.063 | AS43: =Assumptions!$B$44*(1-Assumptions!$B$51)^1 -> 0.063 | AT43: =Assumptions!$B$44*(1-Assumptions!$B$51)^1 -> 0.063 | ... AX43: =Assumptions!$B$44*(1-Assumptions!$B$51)^1 -> 0.063 | AY43: =Assumptions!$B$44*(1-Assumptions!$B$51)^2 -> 0.0567 | AZ43: =Assumptions!$B$44*(1-Assumptions!$B$51)^2 -> 0.0567 | BA43: =Assumptions!$B$44*(1-Assumptions!$B$51)^2 -> 0.0567 | BB43: =Assumptions!$B$44*(1-Assumptions!$B$51)^2 -> 0.0567 | BC43: =Assumptions!$B$44*(1-Assumptions!$B$51)^2 -> 0.0567 | BD43: =Assumptions!$B$44*(1-Assumptions!$B$51)^2 -> 0.0567 | BE43: =Assumptions!$B$44*(1-Assumptions!$B$51)^2 -> 0.0567 | BF43: =Assumptions!$B$44*(1-Assumptions!$B$51)^2 -> 0.0567 | ... BJ43: =Assumptions!$B$44*(1-Assumptions!$B$51)^2 -> 0.0567 | BL43: =AVERAGEIFS($C43:$BJ43,$C$2:$BJ$2,BL$2) -> 0.07 | BM43: =AVERAGEIFS($C43:$BJ43,$C$2:$BJ$2,BM$2) -> 0.07 | BN43: =AVERAGEIFS($C43:$BJ43,$C$2:$BJ$2,BN$2) -> 0.07 | BO43: =AVERAGEIFS($C43:$BJ43,$C$2:$BJ$2,BO$2) -> 0.063 | BP43: =AVERAGEIFS($C43:$BJ43,$C$2:$BJ$2,BP$2) -> 0.0567 | BQ43: =AVERAGE(BL43:BP43) -> 0.06594
A44: H2 Seller churn risk | B44: % | C44: =Assumptions!$B$45 -> 0.02 | D44: =Assumptions!$B$45 -> 0.02 | E44: =Assumptions!$B$45 -> 0.02 | F44: =Assumptions!$B$45 -> 0.02 | G44: =Assumptions!$B$45 -> 0.02 | H44: =Assumptions!$B$45 -> 0.02 | I44: =Assumptions!$B$45 -> 0.02 | J44: =Assumptions!$B$45 -> 0.02 | ... BJ44: =Assumptions!$B$45 -> 0.02 | BL44: =AVERAGEIFS($C44:$BJ44,$C$2:$BJ$2,BL$2) -> 0.02 | BM44: =AVERAGEIFS($C44:$BJ44,$C$2:$BJ$2,BM$2) -> 0.02 | BN44: =AVERAGEIFS($C44:$BJ44,$C$2:$BJ$2,BN$2) -> 0.02 | BO44: =AVERAGEIFS($C44:$BJ44,$C$2:$BJ$2,BO$2) -> 0.02 | BP44: =AVERAGEIFS($C44:$BJ44,$C$2:$BJ$2,BP$2) -> 0.02 | BQ44: =AVERAGE(BL44:BP44) -> 0.02
A45: H2 Off-platform risk | B45: % | C45: =Assumptions!$B$46 -> 0.01 | D45: =Assumptions!$B$46 -> 0.01 | E45: =Assumptions!$B$46 -> 0.01 | F45: =Assumptions!$B$46 -> 0.01 | G45: =Assumptions!$B$46 -> 0.01 | H45: =Assumptions!$B$46 -> 0.01 | I45: =Assumptions!$B$46 -> 0.01 | J45: =Assumptions!$B$46 -> 0.01 | ... BJ45: =Assumptions!$B$46 -> 0.01 | BL45: =AVERAGEIFS($C45:$BJ45,$C$2:$BJ$2,BL$2) -> 0.01 | BM45: =AVERAGEIFS($C45:$BJ45,$C$2:$BJ$2,BM$2) -> 0.01 | BN45: =AVERAGEIFS($C45:$BJ45,$C$2:$BJ$2,BN$2) -> 0.01 | BO45: =AVERAGEIFS($C45:$BJ45,$C$2:$BJ$2,BO$2) -> 0.01 | BP45: =AVERAGEIFS($C45:$BJ45,$C$2:$BJ$2,BP$2) -> 0.01 | BQ45: =AVERAGE(BL45:BP45) -> 0.01
A46: H2 Seller price inflation | B46: % | C46: =Assumptions!$B$48 -> 0.02 | D46: =Assumptions!$B$48 -> 0.02 | E46: =Assumptions!$B$48 -> 0.02 | F46: =Assumptions!$B$48 -> 0.02 | G46: =Assumptions!$B$48 -> 0.02 | H46: =Assumptions!$B$48 -> 0.02 | I46: =Assumptions!$B$48 -> 0.02 | J46: =Assumptions!$B$48 -> 0.02 | ... BJ46: =Assumptions!$B$48 -> 0.02 | BL46: =AVERAGEIFS($C46:$BJ46,$C$2:$BJ$2,BL$2) -> 0.02 | BM46: =AVERAGEIFS($C46:$BJ46,$C$2:$BJ$2,BM$2) -> 0.02 | BN46: =AVERAGEIFS($C46:$BJ46,$C$2:$BJ$2,BN$2) -> 0.02 | BO46: =AVERAGEIFS($C46:$BJ46,$C$2:$BJ$2,BO$2) -> 0.02 | BP46: =AVERAGEIFS($C46:$BJ46,$C$2:$BJ$2,BP$2) -> 0.02 | BQ46: =AVERAGE(BL46:BP46) -> 0.02
A48: H1 % раскатки | B48: % | C48: 0.1 | D48: 0.1 | E48: 0.1 | F48: 0.1 | G48: 0.1 | H48: 0.1 | I48: 0.1 | J48: 0.1 | K48: 0.1 | L48: 0.1 | M48: 0.1 | N48: 0.1 | O48: 0.5 | P48: 0.5 | Q48: 0.5 | R48: 0.5 | S48: 0.5 | T48: 0.5 | U48: 0.5 | V48: 0.5 | W48: 0.5 | X48: 0.5 | Y48: 0.5 | Z48: 0.5 | AA48: 1 | AB48: 1 | AC48: 1 | AD48: 1 | AE48: 1 | AF48: 1 | AG48: 1 | AH48: 1 | AI48: 1 | AJ48: 1 | AK48: 1 | AL48: 1 | AM48: 1 | AN48: 1 | AO48: 1 | AP48: 1 | AQ48: 1 | AR48: 1 | AS48: 1 | AT48: 1 | AU48: 1 | AV48: 1 | AW48: 1 | AX48: 1 | AY48: 1 | AZ48: 1 | BA48: 1 | BB48: 1 | BC48: 1 | BD48: 1 | BE48: 1 | BF48: 1 | BG48: 1 | BH48: 1 | BI48: 1 | BJ48: 1 | BL48: =AVERAGEIFS($C48:$BJ48,$C$2:$BJ$2,BL$2) -> 0.1 | BM48: =AVERAGEIFS($C48:$BJ48,$C$2:$BJ$2,BM$2) -> 0.5 | BN48: =AVERAGEIFS($C48:$BJ48,$C$2:$BJ$2,BN$2) -> 1 | BO48: =AVERAGEIFS($C48:$BJ48,$C$2:$BJ$2,BO$2) -> 1 | BP48: =AVERAGEIFS($C48:$BJ48,$C$2:$BJ$2,BP$2) -> 1 | BQ48: =AVERAGE(BL48:BP48) -> 0.72
A49: H2 % раскатки | B49: % | C49: 0.2 | D49: 0.2 | E49: 0.2 | F49: 0.2 | G49: 0.2 | H49: 0.2 | I49: 0.2 | J49: 0.2 | K49: 0.2 | L49: 0.2 | M49: 0.2 | N49: 0.2 | O49: 0.7 | P49: 0.7 | Q49: 0.7 | R49: 0.7 | S49: 0.7 | T49: 0.7 | U49: 0.7 | V49: 0.7 | W49: 0.7 | X49: 0.7 | Y49: 0.7 | Z49: 0.7 | AA49: 1 | AB49: 1 | AC49: 1 | AD49: 1 | AE49: 1 | AF49: 1 | AG49: 1 | AH49: 1 | AI49: 1 | AJ49: 1 | AK49: 1 | AL49: 1 | AM49: 1 | AN49: 1 | AO49: 1 | AP49: 1 | AQ49: 1 | AR49: 1 | AS49: 1 | AT49: 1 | AU49: 1 | AV49: 1 | AW49: 1 | AX49: 1 | AY49: 1 | AZ49: 1 | BA49: 1 | BB49: 1 | BC49: 1 | BD49: 1 | BE49: 1 | BF49: 1 | BG49: 1 | BH49: 1 | BI49: 1 | BJ49: 1 | BL49: =AVERAGEIFS($C49:$BJ49,$C$2:$BJ$2,BL$2) -> 0.2 | BM49: =AVERAGEIFS($C49:$BJ49,$C$2:$BJ$2,BM$2) -> 0.7 | BN49: =AVERAGEIFS($C49:$BJ49,$C$2:$BJ$2,BN$2) -> 1 | BO49: =AVERAGEIFS($C49:$BJ49,$C$2:$BJ$2,BO$2) -> 1 | BP49: =AVERAGEIFS($C49:$BJ49,$C$2:$BJ$2,BP$2) -> 1 | BQ49: =AVERAGE(BL49:BP49) -> 0.78
A50: Cross-hypothesis synergy | B50: % | C50: =Assumptions!$B$52 -> 0.02 | D50: =Assumptions!$B$52 -> 0.02 | E50: =Assumptions!$B$52 -> 0.02 | F50: =Assumptions!$B$52 -> 0.02 | G50: =Assumptions!$B$52 -> 0.02 | H50: =Assumptions!$B$52 -> 0.02 | I50: =Assumptions!$B$52 -> 0.02 | J50: =Assumptions!$B$52 -> 0.02 | ... BJ50: =Assumptions!$B$52 -> 0.02 | BL50: =AVERAGEIFS($C50:$BJ50,$C$2:$BJ$2,BL$2) -> 0.02 | BM50: =AVERAGEIFS($C50:$BJ50,$C$2:$BJ$2,BM$2) -> 0.02 | BN50: =AVERAGEIFS($C50:$BJ50,$C$2:$BJ$2,BN$2) -> 0.02 | BO50: =AVERAGEIFS($C50:$BJ50,$C$2:$BJ$2,BO$2) -> 0.02 | BP50: =AVERAGEIFS($C50:$BJ50,$C$2:$BJ$2,BP$2) -> 0.02 | BQ50: =AVERAGE(BL50:BP50) -> 0.02
A52: CASE TOTAL
A53: H2 AI Reco % раскатки | B53: % | C53: 0.15 | D53: 0.15 | E53: 0.15 | F53: 0.15 | G53: 0.15 | H53: 0.15 | I53: 0.15 | J53: 0.15 | K53: 0.15 | L53: 0.15 | M53: 0.15 | N53: 0.15 | O53: 0.6 | P53: 0.6 | Q53: 0.6 | R53: 0.6 | S53: 0.6 | T53: 0.6 | U53: 0.6 | V53: 0.6 | W53: 0.6 | X53: 0.6 | Y53: 0.6 | Z53: 0.6 | AA53: 1 | AB53: 1 | AC53: 1 | AD53: 1 | AE53: 1 | AF53: 1 | AG53: 1 | AH53: 1 | AI53: 1 | AJ53: 1 | AK53: 1 | AL53: 1 | AM53: 1 | AN53: 1 | AO53: 1 | AP53: 1 | AQ53: 1 | AR53: 1 | AS53: 1 | AT53: 1 | AU53: 1 | AV53: 1 | AW53: 1 | AX53: 1 | AY53: 1 | AZ53: 1 | BA53: 1 | BB53: 1 | BC53: 1 | BD53: 1 | BE53: 1 | BF53: 1 | BG53: 1 | BH53: 1 | BI53: 1 | BJ53: 1 | BL53: =AVERAGEIFS($C53:$BJ53,$C$2:$BJ$2,BL$2) -> 0.15 | BM53: =AVERAGEIFS($C53:$BJ53,$C$2:$BJ$2,BM$2) -> 0.6 | BN53: =AVERAGEIFS($C53:$BJ53,$C$2:$BJ$2,BN$2) -> 1 | BO53: =AVERAGEIFS($C53:$BJ53,$C$2:$BJ$2,BO$2) -> 1 | BP53: =AVERAGEIFS($C53:$BJ53,$C$2:$BJ$2,BP$2) -> 1 | BQ53: =AVERAGE(BL53:BP53) -> 0.75
A54: Monthly Active Users | B54: mln | C54: =C17*(1+C42*C48)*(1+Assumptions!$B$61*C53) -> 8.1525893 | D54: =D17*(1+D42*D48)*(1+Assumptions!$B$61*D53) -> 8.1858039 | E54: =E17*(1+E42*E48)*(1+Assumptions!$B$61*E53) -> 9.5890129 | F54: =F17*(1+F42*F48)*(1+Assumptions!$B$61*F53) -> 10.08656 | G54: =G17*(1+G42*G48)*(1+Assumptions!$B$61*G53) -> 7.3655662 | H54: =H17*(1+H42*H48)*(1+Assumptions!$B$61*H53) -> 9.2444681 | I54: =I17*(1+I42*I48)*(1+Assumptions!$B$61*I53) -> 8.3539181 | J54: =J17*(1+J42*J48)*(1+Assumptions!$B$61*J53) -> 8.387953 | ... BJ54: =BJ17*(1+BJ42*BJ48)*(1+Assumptions!$B$61*BJ53) -> 14.270164 | BL54: =AVERAGEIFS($C54:$BJ54,$C$2:$BJ$2,BL$2) -> 9.2723826 | BM54: =AVERAGEIFS($C54:$BJ54,$C$2:$BJ$2,BM$2) -> 9.9135774 | BN54: =AVERAGEIFS($C54:$BJ54,$C$2:$BJ$2,BN$2) -> 10.558054 | BO54: =AVERAGEIFS($C54:$BJ54,$C$2:$BJ$2,BO$2) -> 11.085957 | BP54: =AVERAGEIFS($C54:$BJ54,$C$2:$BJ$2,BP$2) -> 11.640255 | BQ54: =AVERAGE(BL54:BP54) -> 10.494045
A55: Items per Order | B55: count | C55: =Assumptions!$B$34*(1+C40*C48) -> 1.015 | D55: =Assumptions!$B$34*(1+D40*D48) -> 1.015 | E55: =Assumptions!$B$34*(1+E40*E48) -> 1.015 | F55: =Assumptions!$B$34*(1+F40*F48) -> 1.015 | G55: =Assumptions!$B$34*(1+G40*G48) -> 1.015 | H55: =Assumptions!$B$34*(1+H40*H48) -> 1.015 | I55: =Assumptions!$B$34*(1+I40*I48) -> 1.015 | J55: =Assumptions!$B$34*(1+J40*J48) -> 1.015 | ... BJ55: =Assumptions!$B$34*(1+BJ40*BJ48) -> 1.1215 | BL55: =AVERAGEIFS($C55:$BJ55,$C$2:$BJ$2,BL$2) -> 1.015 | BM55: =AVERAGEIFS($C55:$BJ55,$C$2:$BJ$2,BM$2) -> 1.075 | BN55: =AVERAGEIFS($C55:$BJ55,$C$2:$BJ$2,BN$2) -> 1.15 | BO55: =AVERAGEIFS($C55:$BJ55,$C$2:$BJ$2,BO$2) -> 1.135 | BP55: =AVERAGEIFS($C55:$BJ55,$C$2:$BJ$2,BP$2) -> 1.1215 | BQ55: =AVERAGE(BL55:BP55) -> 1.0993
A56: AOV | B56: Rub | C56: =C19*(1+C41*C48) -> 2525 | D56: =D19*(1+D41*D48) -> 2554.5802 | E56: =E19*(1+E41*E48) -> 2584.5069 | F56: =F19*(1+F41*F48) -> 2614.7841 | G56: =G19*(1+G41*G48) -> 2645.4161 | H56: =H19*(1+H41*H48) -> 2676.407 | I56: =I19*(1+I41*I48) -> 2707.7608 | J56: =J19*(1+J41*J48) -> 2739.482 | ... BJ56: =BJ19*(1+BJ41*BJ48) -> 5372.7515 | BL56: =AVERAGEIFS($C56:$BJ56,$C$2:$BJ$2,BL$2) -> 2694.2146 | BM56: =AVERAGEIFS($C56:$BJ56,$C$2:$BJ$2,BM$2) -> 3221.0536 | BN56: =AVERAGEIFS($C56:$BJ56,$C$2:$BJ$2,BN$2) -> 3880.6026 | BO56: =AVERAGEIFS($C56:$BJ56,$C$2:$BJ$2,BO$2) -> 4422.1231 | BP56: =AVERAGEIFS($C56:$BJ56,$C$2:$BJ$2,BP$2) -> 5043.4517 | BQ56: =AVERAGE(BL56:BP56) -> 3852.2891
...

Sheet Монетизация и юнит
A1: ПАРАМЕТРЫ ЮНИТ-ЭКОНОМИКИ
A3: Параметр | B3: Значение | C3: Единица | D3: Источник / обоснование
A4: Monthly Retention Rate | B4: 0.925 | C4: % | D4: Fashion ecom retention 31% annually (Shopify 2025) → monthly = 0.40^(1/12) ≈ 92.5%. Avito выше чистого fashion из-за платформенной лояльности. Источник: https://www.shopify.com/blog/average-customer-retention-rate-by-industry
A5: Monthly Churn Rate | B5: =1-B4 -> 0.075 | C5: % | D5: 1 -Retention
A6: Average Lifetime (months) | B6: =1/B5 -> 13.333333 | C6: мес | D6: 1 /Monthly Churn
A7: CAC (buyer, blended) — по годам, см. ниже | B7: =Assumptions!$B$65 -> 250 | C7: руб | D7: CAC растёт ~15% YoY при масштабировании через платные каналы. Бенчмарк: C2C marketplace buyer CAC $20-50 (financialmodelslab.com). Значения: 2026=250р, 2027=300р, 2028=350р, 2029=400р, 2030=450р. Источник: Assumptions B65-B69.
A8: Purchases per buyer per year | B8: 4 | C8: шт | D8: Бенчмарк fashion C2C: 3-5 покупок/год. Avito Fashion — средний сценарий.
A9: Share of paying users (CR × Delivery) | B9: =Assumptions!B15*Assumptions!B16 -> 0.0111 | C9: % | D9: CR *Delivery Share (из Assumptions)
A10: Discount rate (monthly) | B10: 0.01 | C10: % | D10: Для расчёта DCF LTV. ~12% годовых → 1% в месяц.
A13: РАСЧЁТ ARPU, CAC, LTV
A15: Метрика | B15: Единица | C15: 2026 | D15: 2027 | E15: 2028 | F15: 2029 | G15: 2030
A16: MAU (avg monthly, Case Total) | B16: mln | C16: ='Traction model'!BL54 -> 9.2723826 | D16: ='Traction model'!BM54 -> 9.9135774 | E16: ='Traction model'!BN54 -> 10.558054 | F16: ='Traction model'!BO54 -> 11.085957 | G16: ='Traction model'!BP54 -> 11.640255
A17: Annual Revenue (Case Total) | B17: mln руб | C17: ='Traction model'!BL67 -> 12481.237 | D17: ='Traction model'!BM67 -> 13050.726 | E17: ='Traction model'!BN67 -> 13674.84 | F17: ='Traction model'!BO67 -> 14408.415 | G17: ='Traction model'!BP67 -> 15188.75
A18: ARPU (monthly) | B18: руб | C18: =C17*1000000/12/C16/1000000 -> 112.17215 | D18: =D17*1000000/12/D16/1000000 -> 109.70414 | E18: =E17*1000000/12/E16/1000000 -> 107.93371 | F18: =F17*1000000/12/F16/1000000 -> 108.30831 | G18: =G17*1000000/12/G16/1000000 -> 108.73724
A19: ARPU (annual) | B19: руб | C19: =C18*12 -> 1346.0658 | D19: =D18*12 -> 1316.4497 | E19: =E18*12 -> 1295.2046 | F19: =F18*12 -> 1299.6997 | G19: =G18*12 -> 1304.8469
A20: CAC | B20: руб | C20: =Assumptions!$B$65 -> 250 | D20: =Assumptions!$B$66 -> 300 | E20: =Assumptions!$B$67 -> 350 | F20: =Assumptions!$B$68 -> 400 | G20: =Assumptions!$B$69 -> 450
A21: LTV (simple) | B21: руб | C21: =C18*$B$6 -> 1495.6287 | D21: =D18*$B$6 -> 1462.7219 | E21: =E18*$B$6 -> 1439.1162 | F21: =F18*$B$6 -> 1444.1108 | G21: =G18*$B$6 -> 1449.8299
A22: LTV (DCF, discounted) | B22: руб | C22: =C18*$B$4/(1+$B$10-$B$4) -> 1220.6969 | D22: =D18*$B$4/(1+$B$10-$B$4) -> 1193.8392 | E22: =E18*$B$4/(1+$B$10-$B$4) -> 1174.5728 | F22: =F18*$B$4/(1+$B$10-$B$4) -> 1178.6493 | G22: =G18*$B$4/(1+$B$10-$B$4) -> 1183.317
A23: LTV / CAC | B23: x | C23: =C21/C20 -> 5.9825147 | D23: =D21/D20 -> 4.8757397 | E23: =E21/E20 -> 4.1117605 | F23: =F21/F20 -> 3.610277 | G23: =G21/G20 -> 3.2218442
A24: Payback Period | B24: мес | C24: =C20/C18 -> 2.2287172 | D24: =D20/D18 -> 2.7346278 | E24: =E20/E18 -> 3.242731 | F24: =F20/F18 -> 3.6931607 | G24: =G20/G18 -> 4.1384166
A25: ARPPU (monthly, per paying user) | B25: руб | C25: =C18/$B$9 -> 10105.599 | D25: =D18/$B$9 -> 9883.2562 | E25: =E18/$B$9 -> 9723.758 | F25: =F18/$B$9 -> 9757.5055 | G25: =G18/$B$9 -> 9796.1478
A28: СРАВНЕНИЕ: Baseline vs Case Total
A30: Метрика | B30: Ед. | C30: 2026 Base | D30: 2026 Case | E30: 2028 Base | F30: 2028 Case | G30: 2030 Base | H30: 2030 Case
A31: Monthly ARPU | B31: руб | C31: ='Traction model'!BL37*1000000/12/'Traction model'!BL17/1000000 -> 113.17125 | D31: =C18 -> 112.17215 | E31: ='Traction model'!BN37*1000000/12/'Traction model'!BN17/1000000 -> 113.77472 | F31: =E18 -> 107.93371 | G31: ='Traction model'!BP37*1000000/12/'Traction model'!BP17/1000000 -> 114.57282 | H31: =G18 -> 108.73724
A32: LTV | B32: руб | C32: =C31*$B$6 -> 1508.95 | D32: =D31*$B$6 -> 1495.6287 | E32: =E31*$B$6 -> 1516.9963 | F32: =F31*$B$6 -> 1439.1162 | G32: =G31*$B$6 -> 1527.6376 | H32: =H31*$B$6 -> 1449.8299
A33: LTV/CAC | B33: x | C33: =C32/C20 -> 6.0357998 | D33: =D32/C20 -> 5.9825147 | E33: =E32/E20 -> 4.3342752 | F33: =F32/E20 -> 4.1117605 | G33: =G32/G20 -> 3.3947503 | H33: =H32/G20 -> 3.2218442
A36: SENSITIVITY: LTV при разном Retention
A38: Monthly Retention | B38: Lifetime (мес) | C38: LTV 2026 (руб) | D38: LTV 2028 (руб) | E38: LTV 2030 (руб)
A39: 0.85 | B39: =1/(1-A39) -> 6.6666667 | C39: =C18*B39 -> 747.81434 | D39: =E18*B39 -> 719.55809 | E39: =G18*B39 -> 724.91493
A40: 0.875 | B40: =1/(1-A40) -> 8 | C40: =C18*B40 -> 897.37721 | D40: =E18*B40 -> 863.46971 | E40: =G18*B40 -> 869.89792
A41: 0.9 | B41: =1/(1-A41) -> 10 | C41: =C18*B41 -> 1121.7215 | D41: =E18*B41 -> 1079.3371 | E41: =G18*B41 -> 1087.3724
A42: 0.925 | B42: =1/(1-A42) -> 13.333333 | C42: =C18*B42 -> 1495.6287 | D42: =E18*B42 -> 1439.1162 | E42: =G18*B42 -> 1449.8299
A43: 0.95 | B43: =1/(1-A43) -> 20 | C43: =C18*B43 -> 2243.443 | D43: =E18*B43 -> 2158.6743 | E43: =G18*B43 -> 2174.7448
A44: 0.96 | B44: =1/(1-A44) -> 25 | C44: =C18*B44 -> 2804.3038 | D44: =E18*B44 -> 2698.3428 | E44: =G18*B44 -> 2718.431
A45: 0.97 | B45: =1/(1-A45) -> 33.333333 | C45: =C18*B45 -> 3739.0717 | D45: =E18*B45 -> 3597.7905 | E45: =G18*B45 -> 3624.5747
A46: 0.98 | B46: =1/(1-A46) -> 50 | C46: =C18*B46 -> 5608.6076 | D46: =E18*B46 -> 5396.6857 | E46: =G18*B46 -> 5436.862
A85: ПРОВЕРКА ДОПУЩЕНИЙ
A87: Допущение | B87: Значение | C87: Когда проверить | D87: Как проверить
A88: Monthly Retention 92.5% | B88: =B4 -> 0.925 | C88: Через 3 мес после запуска | D88: Когортный анализ: % MAU, вернувшихся через 30 дней. Сегментация по fashion-only пользователям.
A89: CAC растёт по годам (2026-2030) | B89: =B7 -> 250 | C89: Сразу | D89: CAC 2026=250, 2027=300, 2028=350, 2029=400, 2030=450. Источник: Assumptions B65-B69.
...

Sheet Checkers
A1: ЧЕКЕРЫ ВАЛИДАЦИИ МОДЕЛИ
A3: Проверка | B3: Формула / значение | C3: Статус | D3: Комментарий
A4: ЛОГИЧЕСКИЕ ПРОВЕРКИ
A5: Revenue Case > Revenue Baseline (2028) | B5: =IF('Traction model'!BN67>'Traction model'!BN37,"✓ OK","✗ ОШИБКА") -> ✗ ОШИБКА | D5: Гипотезы должны давать прирост total revenue (Transaction + VAS) vs baseline
A6: GMV Case > 0 (all months) | B6: =IF(MIN('Traction model'!C62:'Traction model'!BJ62)>0,"✓ OK","✗ ОШИБКА") -> ✓ OK | D6: GMV не может быть отрицательным
A7: Take Rate Case в диапазоне 5-12% | B7: =IF(AND(MIN('Traction model'!C63:'Traction model'!BJ63)>=0.05,MAX('Traction model'!C63:'Traction model'!BJ63)<=0.12),"✓ OK","✗ ОШИБКА") -> ✓ OK | D7: Take Rate должен быть реалистичным
A8: MAU Case ≤ MAU Baseline × 1.1 | B8: =IF(MAX('Traction model'!C54:BJ54)<=MAX('Traction model'!C17:BJ17)*1.1,"✓ OK","✗ ВНИМАНИЕ") -> ✓ OK | D8: H2 AI Retention uplift (+5%) при полной раскатке даёт +4% MAU сверх Baseline. Порог 10% — контроль нереалистичного роста.
A9: Orders Fulfilled > 0 (all months) | B9: =IF(MIN('Traction model'!C61:'Traction model'!BJ61)>0,"✓ OK","✗ ОШИБКА") -> ✓ OK | D9: Заказы не могут быть отрицательными
A10: LTV/CAC > 1 (2028) | B10: =IF('Монетизация и юнит'!E23>1,"✓ OK","✗ ОШИБКА") -> ✓ OK | D10: Юнит-экономика должна быть положительной
A11: H1 каннибализация применена (Orders Case < MAU Case × CR) | B11: =IF('Traction model'!C58<'Traction model'!C54*1000000*'Traction model'!C21,"✓ OK (H1 cannib снижает заказы от MAU×CR)","✗ Каннибализация не работает") -> ✓ OK (H1 cannib снижает заказы от MAU×CR) | D11: H1 Bundle каннибализация (коэфф 0.97) снижает Orders vs "чистого" MAU×CR. Orders Case < MAU_Case × CR × 1M. В новой модели Orders Case > Baseline нормально — H2 AI растит MAU.
A12: H2 AI Retention uplift положителен (MAU Case ≥ MAU Baseline) | B12: =IF('Traction model'!C54>='Traction model'!C17,"✓ OK (H2 AI retention поднимает MAU сверх baseline)","✗ H2 AI retention не работает") -> ✓ OK (H2 AI retention поднимает MAU сверх baseline) | D12: H2 AI Reco улучшает retention (+5%), что перевешивает H1 retention decay (-1%). Итого MAU Case > MAU Baseline. Это ожидаемое поведение новой H2.
A14: ТЕХНИЧЕСКИЕ ПРОВЕРКИ
A15: Нет зашитых чисел в Baseline | B15: ="✓ Все формулы ссылаются на Assumptions" -> ✓ Все формулы ссылаются на Assumptions | D15: CR, Delivery, Return Rate, Take Rate, AOV, MAU — все из Assumptions
A16: Нет зашитых чисел в Case Total | B16: ="✓ Все формулы ссылаются на Assumptions и Hypotheses inputs" -> ✓ Все формулы ссылаются на Assumptions и Hypotheses inputs | D16: Uplift, rollout, churn, cannibalization — все параметризованы
A17: Консистентность временных рамок | B17: ="✓ Все расчёты помесячные (C-BJ), годовые итоги (BL-BP)" -> ✓ Все расчёты помесячные (C-BJ), годовые итоги (BL-BP) | D17: Inflation и growth пересчитаны из YoY в monthly через POWER
A18: Каскадирование метрик | B18: ="✓ MAU → CR → Orders → Delivery → Fulfilled → GMV → Revenue" -> ✓ MAU → CR → Orders → Delivery → Fulfilled → GMV → Revenue | D18: Каждая метрика зависит от предыдущей, нет пропусков
A19: Seasonal coefficients sum ≈ 12 | B19: =IF(ABS(SUM(Assumptions!B20:B31)-12)<0.5,"✓ OK (sum="&ROUND(SUM(Assumptions!B20:B31),2)&")","✗ ОШИБКА") -> ✓ OK (sum=12) | D19: Сумма сезонных коэффициентов должна быть ≈ 12 (среднее ≈ 1)
A20: AOV растёт с инфляцией | B20: =IF('Traction model'!N19>'Traction model'!C19,"✓ OK (Dec > Jan)","✗ ОШИБКА") -> ✓ OK (Dec > Jan) | D20: AOV должен монотонно расти за счёт инфляции
A22: ПРОВЕРКИ РЕАЛИСТИЧНОСТИ
A23: Market Share (GMV/SAM) < 5% | B23: =IF(MAX('Traction model'!C31:'Traction model'!BJ31)/MAX('Traction model'!C8:'Traction model'!BJ8)<0.05,"✓ OK","✗ Доля рынка нереалистична") -> ✗ Доля рынка нереалистична | D23: Доля рынка не должна быть слишком высокой для C2C fashion
A24: MAU рост CAGR ~5% | B24: =IF(AND('Traction model'!BP17/'Traction model'!BL17>1.03,'Traction model'!BP17/'Traction model'!BL17<1.08),"✓ OK","✗ Рост MAU нереалистичен") -> ✗ Рост MAU нереалистичен | D24: Ожидаемый CAGR MAU 5% (Strategy Scale)
A25: CR 3% — бенчмарк C2C fashion | B25: =IF(Assumptions!B15=0.03,"✓ OK (3%)","✗ CR отличается от бенчмарка") -> ✓ OK (3%) | D25: Бенчмарк C2C fashion: 2-4% CR (Vinted ~2.5-3%)
A26: Take Rate 7% в диапазоне 5-10% | B26: =IF(AND(Assumptions!B19>=0.05,Assumptions!B19<=0.1),"✓ OK","✗ Вне диапазона") -> ✓ OK | D26: Задано в условиях ДЗ: Take Rate 5-10%
A27: Return Rate 10% — бенчмарк fashion | B27: =IF(AND(Assumptions!B17>=0.05,Assumptions!B17<=0.3),"✓ OK","✗ Вне бенчмарка") -> ✓ OK | D27: Fashion ecom: 10-30% returns. 10% — консервативно для C2C (без примерки)
A28: Fashion resale market 253 млрд руб 2025 | B28: ="Бенчмарк: Коммерсант, 2025" -> Бенчмарк: Коммерсант, 2025 | D28: Рынок fashion-ресейла 253 млрд руб (2025). Источник: https://www.kommersant.ru/doc/8420884
A29: НОВЫЕ ПРОВЕРКИ (VAS + AI Reco + CAC)
A30: VAS Revenue > 0 (all months) | B30: =IF(MIN('Traction model'!C36:BJ36)>0,"✓ OK","✗ ОШИБКА") -> ✓ OK | D30: VAS не может быть отрицательным
A31: VAS Revenue < Transaction Revenue × 50 | B31: =IF(MAX('Traction model'!C36:BJ36)<MAX('Traction model'!C35:BJ35)*50,"✓ OK","✗ Sanity check VAS") -> ✓ OK | D31: Санчек: VAS не должен быть абсурдно большим
A32: ARPU ~100 руб/мес (2026) | B32: =IF(ABS('Монетизация и юнит'!C18-100)<50,"✓ OK (~"&ROUND('Монетизация и юнит'!C18,0)&" руб/мес)","✗ ARPU далёко от 100 руб") -> ✓ OK (~112 руб/мес) | D32: Должен соответствовать данным ДЗ №2 (ARPU ~100 руб/мес)
A33: CAC растёт по годам (2026→2030) | B33: =IF(Assumptions!B69>Assumptions!B65,"✓ OK (CAC2030="&Assumptions!B69&" > CAC2026="&Assumptions!B65&")","✗ CAC не растёт") -> ✓ OK (CAC2030=450 > CAC2026=250) | D33: CAC 2030 > CAC 2026 при масштабировании
A34: H2 AI GMV uplift ≤ 20% | B34: =IF(Assumptions!B58<=0.2,"✓ OK ("&TEXT(Assumptions!B58,"0%")&")","✗ GMV uplift нереалистичен") -> ✓ OK (15%) | D34: AI-рекомендации не должны давать нереалистичный uplift
A35: Total Revenue (2026) ≈ MAU × ARPU target | B35: =IF(ABS('Traction model'!BL67-'Traction model'!BL17*1000000*100*12/1000000)/'Traction model'!BL67<0.5,"✓ OK","✗ Revenue/ARPU несоответствие") -> ✓ OK | D35: Сверка с ARPU из данных ДЗ №2: Total Revenue ≈ MAU × 100 руб/мес × 12
A36: VAS Revenue Case > 0 (all months) | B36: =IF(MIN('Traction model'!C66:BJ66)>0,"✓ OK","✗ VAS Case отрицательный") -> ✓ OK | D36: VAS Revenue Case не может быть отрицательным

Sheet PnL
A1: ДЗ №4 · Планирование затрат, PnL и CashFlow | Avito «Мода и одежда»
A2: Гипотезы: Bundle Offers (H1) + AI Recommendations (H2) | Монетизация: Transactional 7% + CPA 5%
A4: БЛОК ДОПУЩЕНИЙ — все входные параметры
B5: Параметр | C5: Значение | D5: Единица | E5: Источник / Обоснование
B6: РЫНОК И ПРОДУКТ
B7: Base MAU Fashion | C7: 9 | D7: млн | E7: Данные Avito, ДЗ №1
B8: MAU Growth YoY | C8: 0.05 | D8: % | E8: Стратегия Scale (5%/год)
B9: CR MAU → Order | C9: 0.03 | D9: % | E9: Данные ДЗ №2, бенчмарк C2C
B10: Delivery Share | C10: 0.37 | D10: % | E10: Экспертная оценка (рост TRX)
B11: Return Rate | C11: 0.1 | D11: % | E11: Бенчмарк fashion e-com
B12: AOV 2026 | C12: 2500 | D12: руб | E12: Рыночный бенчмарк C2C fashion
B13: AOV Inflation YoY | C13: 0.15 | D13: % | E13: Инфляция fashion ~15%/год (Коммерсант 2025)
B14: Take Rate (base) | C14: 0.07 | D14: % | E14: ДЗ №2, конкурентный диапазон 5-10%
B15: VAS: Seller Share of MAU | C15: 0.28 | D15: % | E15: ДЗ №1, ~6 млн объявлений при 9 млн MAU
B16: VAS: Adoption Rate | C16: 0.15 | D16: % | E16: ДЗ №2, 15% активных продавцов используют VAS
B17: VAS: Avg Spend (руб/мес/продавец) | C17: 2650 | D17: руб/мес | E17: Расчёт из ARPU-target ДЗ №2
B18: ГИПОТЕЗЫ РОСТА
B19: H1 Bundle: AOV uplift | C19: 0.1 | D19: % | E19: Vinted: avg bundle = 3.5 товара → +10% AOV. CLOSO 2024
B20: AI Reco: GMV per buyer uplift (2026–2028) | C20: 0.15 | D20: % | E20: Amazon/Netflix AI рекомендации +15% GMV per buyer. McKinsey 2024
B21: AI Reco: GMV uplift 2029 (decay -10%) | C21: 0.135 | D21: % | E21: Затухание: 2028×0.9 = 13.5%
B22: AI Reco: GMV uplift 2030 (decay -10%) | C22: 0.1215 | D22: % | E22: Затухание: 2029×0.9 = 12.15%
B23: Cross-hypothesis synergy | C23: 0.02 | D23: % | E23: Бандлы усиливают AI-рекомендации (больше комплектов в ленте) → +2%
B24: Effect decay annual (с 2029) | C24: 0.1 | D24: % | E24: VWO Benchmark 2024: -10%/год после полной раскатки
B25: Cannibalization (orders, H1) | C25: 0.03 | D25: % | E25: Из 20% бандл-заказов лишь 15% замещают два отдельных → 3% снижение TRX
B26: VAS cannibalization (AI Reco) | C26: 0.02 | D26: % | E26: AI-буст органики снижает VAS-расходы продавцов на 2%
B27: КОМАНДА — ставки из таблицы ДЗ №4
B28: Tech Lead (Тимлид, Senior) — годовая ЗП | C28: 6000 | D28: тыс.руб/год | E28: Таблица ДЗ №4, Senior
B29: Backend (Senior) — годовая ЗП | C29: 5400 | D29: тыс.руб/год | E29: Таблица ДЗ №4, Senior. 2 FTE в фазе разработки
B30: Frontend (Senior) — годовая ЗП | C30: 4800 | D30: тыс.руб/год | E30: Таблица ДЗ №4, Senior
B31: iOS (Senior) — годовая ЗП | C31: 5000 | D31: тыс.руб/год | E31: Таблица ДЗ №4, Senior
B32: Android (Senior) — годовая ЗП | C32: 4800 | D32: тыс.руб/год | E32: Таблица ДЗ №4, Senior
B33: QA-инженер (Manual+Auto) — годовая ЗП | C33: 3400 | D33: тыс.руб/год | E33: Таблица ДЗ №4, Manual + Automation
B34: Продуктовый дизайнер (Middle/Senior) — годовая ЗП | C34: 3600 | D34: тыс.руб/год | E34: Таблица ДЗ №4, Middle/Senior
B35: Продуктовый аналитик (Middle/Senior) — годовая ЗП | C35: 3800 | D35: тыс.руб/год | E35: Таблица ДЗ №4, Middle/Senior
B36: Социальные взносы (IT-льгота) | C36: 0.15 | D36: % | E36: Avito — аккредитованная IT-компания. IT-льгота: страх. взносы ~7.6% выше порога + прочие ~7% = ~15% к gross. Ставка сущ. ниже стандарт. 30%
B37: Индексация ЗП (YoY) | C37: 0.1 | D37: % | E37: Рост рынка труда IT-специалистов ~10%/год (SuperJob 2025)
B38: TtM — TIME TO MARKET (ФАЗЫ РЕАЛИЗАЦИИ)
B39: Фаза 1: Discovery & Design | C39: 1 | D39: мес | E39: Тимлид + Аналитик + Дизайнер: scope, user research, wireframes, CPA-договоры
B40: Фаза 2: Development | C40: 4 | D40: мес | E40: Вся команда 9 FTE: backend API (Bundle+CPA), frontend UI, mobile apps, QA-подготовка, MLOps инфра
B41: Фаза 3: QA & Stabilization | C41: 1.5 | D41: мес | E41: Тимлид + Backend×2 + QA + Аналитик: тестирование, баг-фикс, нагрузочные тесты, pre-launch review
...
