Workbook

Sheet FinSummary
A1: Avito Confidential
A3: 1 | B3: GENERAL INFORMATION
B4: Project name | D4: Avito Животные - 3 гипотезы (рекомендации, индикатор цены, видео)
B5: Project leader | D5: Коростелев Александр | K5: CF cumulative (5 лет, INCR) | L5: =CashFlow!BK30 -> 100.73241
K6: Current request (peak funding need) | L6: =CashFlow!C33 -> -8.3612993
K7: Negative CF (minimum) | L7: =CashFlow!C33 -> -8.3612993
K8: NPV (WACC 26,3%, 5 лет) | L8: =CashFlow!C36 -> 47.843436
B12: Parameter | C12: Units | D12: base | E12: 2026 | F12: 2027 | G12: 2028 | H12: 2029 | I12: 2030
A13: 2 | B13: ASSUMPTIONS
B14: Project start date | D14: 2026-01-01
B15: WACC | D15: =PnL!B10 -> 0.263
B16: TGR | D16: =PnL!B11 -> 0.05
B17: Income Tax | E17: 0.05 | F17: 0.05 | G17: 0.05 | H17: 0.05 | I17: 0.05
B18: НДС | E18: 0.2 | F18: 0.22 | G18: 0.22 | H18: 0.22 | I18: 0.22
B21: Revenue effect (cannibalization) | D21: no | E21: Каннибализация не учтена - гипотезы добавляют новые сценарии (рекомендации профи, индикатор цены, видео в карточках), не отнимая трафик у существующих видов монетизации. Анализ риска - см. ДЗ2.
B22: Cannibalization object | D22: n/a
B23: Incremental revenue methodology | D23: 1 - uplift as % (× rollout × confidence rate) | E23: Каждая гипотеза имеет: uplift к метрике, % раскатки по годам (W1: 30/70/100/100/100; W2: 10/50/100/100/100; W3: 30/100/100/100/100), confidence rate (W1: 0.75, W2: 0.6, W3: 0.4). Итог = ARPPU × Uplift × Rollout × Confidence.
B24: Revenue calc method | D24: 1 - uplift as %
A27: 3 | B27: FINANCIALS AS IS
B28: Revenue | C28: mR | E28: =PnL!BL20 -> 409.36014 | F28: =PnL!BM20 -> 412.94306 | G28: =PnL!BN20 -> 429.46078 | H28: =PnL!BO20 -> 446.63921 | I28: =PnL!BP20 -> 464.50478
B29: CoS | C29: mR | E29: =PnL!BL21 -> -8.1872029 | F29: =PnL!BM21 -> -8.2588611 | G29: =PnL!BN21 -> -8.5892156 | H29: =PnL!BO21 -> -8.9327842 | I29: =PnL!BP21 -> -9.2900956
B30: Staff costs | C30: mR | E30: =PnL!BL22 -> -84 | F30: =PnL!BM22 -> -89.88 | G30: =PnL!BN22 -> -96.1716 | H30: =PnL!BO22 -> -102.90361 | I30: =PnL!BP22 -> -110.10686
B31: Marketing | C31: mR | E31: =PnL!BL23 -> -20.468007 | F31: =PnL!BM23 -> -20.647153 | G31: =PnL!BN23 -> -21.473039 | H31: =PnL!BO23 -> -22.33196 | I31: =PnL!BP23 -> -23.225239
B32: Consulting | C32: mR | E32: =PnL!BL24 -> 0 | F32: =PnL!BM24 -> 0 | G32: =PnL!BN24 -> 0 | H32: =PnL!BO24 -> 0 | I32: =PnL!BP24 -> 0
B33: IT Costs | C33: mR | E33: =PnL!BL25 -> -3 | F33: =PnL!BM25 -> -3 | G33: =PnL!BN25 -> -3 | H33: =PnL!BO25 -> -3 | I33: =PnL!BP25 -> -3
B34: G&A Costs | C34: mR | E34: =PnL!BL26 -> -4.2 | F34: =PnL!BM26 -> -4.494 | G34: =PnL!BN26 -> -4.80858 | H34: =PnL!BO26 -> -5.1451806 | I34: =PnL!BP26 -> -5.5053432
B35: Other Costs | C35: mR | E35: =PnL!BL27 -> 0 | F35: =PnL!BM27 -> 0 | G35: =PnL!BN27 -> 0 | H35: =PnL!BO27 -> 0 | I35: =PnL!BP27 -> 0
B36: EBITDA | C36: mR | E36: =PnL!BL28 -> 289.50493 | F36: =PnL!BM28 -> 286.66304 | G36: =PnL!BN28 -> 295.41834 | H36: =PnL!BO28 -> 304.32567 | I36: =PnL!BP28 -> 313.37724
B37: Income Tax | C37: mR | E37: =PnL!BL30 -> -14.475247 | F37: =PnL!BM30 -> -14.333152 | G37: =PnL!BN30 -> -14.770917 | H37: =PnL!BO30 -> -15.216284 | I37: =PnL!BP30 -> -15.668862
B38: EBITDA margin | C38: % | E38: =IFERROR(PnL!BL28/PnL!BL20,0) -> 0.70721329 | F38: =IFERROR(PnL!BM28/PnL!BM20,0) -> 0.69419509 | G38: =IFERROR(PnL!BN28/PnL!BN20,0) -> 0.68788201 | H38: =IFERROR(PnL!BO28/PnL!BO20,0) -> 0.68136802 | I38: =IFERROR(PnL!BP28/PnL!BP20,0) -> 0.67464803
B39: Change in NWC | C39: mR | E39: =PnL!BL35 -> -74.521272 | F39: =PnL!BM35 -> -2.9798509 | G39: =PnL!BN35 -> -3.0975749 | H39: =PnL!BO35 -> -3.219905 | I39: =PnL!BP35 -> -3.3470182
B40: FCF (free cash flow) | C40: mR | E40: =PnL!BL36 -> 200.50841 | F40: =PnL!BM36 -> 269.35004 | G40: =PnL!BN36 -> 277.54985 | H40: =PnL!BO36 -> 285.88948 | I40: =PnL!BP36 -> 294.36136
A44: 4 | B44: FINANCIALS INCREMENT
B45: Revenue | C45: mR | E45: =PnL!BL39 -> 12.39892 | F45: =PnL!BM39 -> 29.299167 | G45: =PnL!BN39 -> 30.769894 | H45: =PnL!BO39 -> 32.000806 | I45: =PnL!BP39 -> 33.280838
B46: CoS | C46: mR | E46: =PnL!BL40 -> -0.4959568 | F46: =PnL!BM40 -> -1.1719667 | G46: =PnL!BN40 -> -1.2307957 | H46: =PnL!BO40 -> -1.2800322 | I46: =PnL!BP40 -> -1.3312335
B47: Staff costs | C47: mR | E47: =PnL!BL41 -> -12.510652 | F47: =PnL!BM41 -> -3.371065 | G47: =PnL!BN41 -> -3.6070395 | H47: =PnL!BO41 -> -3.8595323 | I47: =PnL!BP41 -> -4.1296995
B48: Marketing | C48: mR | E48: =PnL!BL42 -> -1.6666667 | F48: =PnL!BM42 -> -3.5833333 | G48: =PnL!BN42 -> -3 | H48: =PnL!BO42 -> -3 | I48: =PnL!BP42 -> -3
B49: Consulting | C49: mR | E49: =PnL!BL43 -> 0 | F49: =PnL!BM43 -> 0 | G49: =PnL!BN43 -> 0 | H49: =PnL!BO43 -> 0 | I49: =PnL!BP43 -> 0
B50: IT Costs | C50: mR | E50: =PnL!BL44 -> -2.5 | F50: =PnL!BM44 -> -2.1 | G50: =PnL!BN44 -> -1.5 | H50: =PnL!BO44 -> -1.5 | I50: =PnL!BP44 -> -1.5
B51: G&A Costs | C51: mR | E51: =PnL!BL45 -> -0.6255326 | F51: =PnL!BM45 -> -0.16855325 | G51: =PnL!BN45 -> -0.18035198 | H51: =PnL!BO45 -> -0.19297661 | I51: =PnL!BP45 -> -0.20648498
...

Sheet PnL
A1: Avito Animals - PnL: Развитие классифайдной монетизации
A2: 1. GENERAL INFORMATION
A3: Project name | B3: Avito Animals - Алгоритм рекомендаций + Индикатор цены + Видео в карточках
A4: Project leader | B4: Коростелев Александр
A5: Period | B5: 2026-2030 (5 лет)
A6: Currency | B6: млн ₽
A8: 2. ASSUMPTIONS
A9: Project start date | B9: 2026-01-01
A10: WACC | B10: 0.263
A11: TGR | B11: 0.05
A12: Income Tax | D12: 0.05 | E12: 0.05 | F12: 0.05 | G12: 0.05 | H12: 0.05 | I12: 0.05 | J12: 0.05 | K12: 0.05 | L12: 0.05 | M12: 0.05 | N12: 0.05 | O12: 0.05 | P12: 0.05 | Q12: 0.05 | R12: 0.05 | S12: 0.05 | T12: 0.05 | U12: 0.05 | V12: 0.05 | W12: 0.05 | X12: 0.05 | Y12: 0.05 | Z12: 0.05 | AA12: 0.05 | AB12: 0.05 | AC12: 0.05 | AD12: 0.05 | AE12: 0.05 | AF12: 0.05 | AG12: 0.05 | AH12: 0.05 | AI12: 0.05 | AJ12: 0.05 | AK12: 0.05 | AL12: 0.05 | AM12: 0.05 | AN12: 0.05 | AO12: 0.05 | AP12: 0.05 | AQ12: 0.05 | AR12: 0.05 | AS12: 0.05 | AT12: 0.05 | AU12: 0.05 | AV12: 0.05 | AW12: 0.05 | AX12: 0.05 | AY12: 0.05 | AZ12: 0.05 | BA12: 0.05 | BB12: 0.05 | BC12: 0.05 | BD12: 0.05 | BE12: 0.05 | BF12: 0.05 | BG12: 0.05 | BH12: 0.05 | BI12: 0.05 | BJ12: 0.05 | BK12: 0.05
A13: НДС | D13: 0.2 | E13: 0.2 | F13: 0.2 | G13: 0.2 | H13: 0.2 | I13: 0.2 | J13: 0.2 | K13: 0.2 | L13: 0.2 | M13: 0.2 | N13: 0.2 | O13: 0.2 | P13: 0.22 | Q13: 0.22 | R13: 0.22 | S13: 0.22 | T13: 0.22 | U13: 0.22 | V13: 0.22 | W13: 0.22 | X13: 0.22 | Y13: 0.22 | Z13: 0.22 | AA13: 0.22 | AB13: 0.22 | AC13: 0.22 | AD13: 0.22 | AE13: 0.22 | AF13: 0.22 | AG13: 0.22 | AH13: 0.22 | AI13: 0.22 | AJ13: 0.22 | AK13: 0.22 | AL13: 0.22 | AM13: 0.22 | AN13: 0.22 | AO13: 0.22 | AP13: 0.22 | AQ13: 0.22 | AR13: 0.22 | AS13: 0.22 | AT13: 0.22 | AU13: 0.22 | AV13: 0.22 | AW13: 0.22 | AX13: 0.22 | AY13: 0.22 | AZ13: 0.22 | BA13: 0.22 | BB13: 0.22 | BC13: 0.22 | BD13: 0.22 | BE13: 0.22 | BF13: 0.22 | BG13: 0.22 | BH13: 0.22 | BI13: 0.22 | BJ13: 0.22 | BK13: 0.22
A14: Cannibalization | B14: Не учтена (см. ДЗ2), так как инициативы направлены на повышение конверсий и не влияют на переток пользователей из других категорий
A16: Параметр | B16: Ед. изм. | D16: 2026 | E16: 2026 | F16: 2026 | G16: 2026 | H16: 2026 | I16: 2026 | J16: 2026 | K16: 2026 | L16: 2026 | M16: 2026 | N16: 2026 | O16: 2026 | P16: 2027 | Q16: 2027 | R16: 2027 | S16: 2027 | T16: 2027 | U16: 2027 | V16: 2027 | W16: 2027 | X16: 2027 | Y16: 2027 | Z16: 2027 | AA16: 2027 | AB16: 2028 | AC16: 2028 | AD16: 2028 | AE16: 2028 | AF16: 2028 | AG16: 2028 | AH16: 2028 | AI16: 2028 | AJ16: 2028 | AK16: 2028 | AL16: 2028 | AM16: 2028 | AN16: 2029 | AO16: 2029 | AP16: 2029 | AQ16: 2029 | AR16: 2029 | AS16: 2029 | AT16: 2029 | AU16: 2029 | AV16: 2029 | AW16: 2029 | AX16: 2029 | AY16: 2029 | AZ16: 2030 | BA16: 2030 | BB16: 2030 | BC16: 2030 | BD16: 2030 | BE16: 2030 | BF16: 2030 | BG16: 2030 | BH16: 2030 | BI16: 2030 | BJ16: 2030 | BK16: 2030 | BL16: 2026 Total | BM16: 2027 Total | BN16: 2028 Total | BO16: 2029 Total | BP16: 2030 Total
D17: Jan | E17: Feb | F17: Mar | G17: Apr | H17: May | I17: Jun | J17: Jul | K17: Aug | L17: Sep | M17: Oct | N17: Nov | O17: Dec | P17: Jan | Q17: Feb | R17: Mar | S17: Apr | T17: May | U17: Jun | V17: Jul | W17: Aug | X17: Sep | Y17: Oct | Z17: Nov | AA17: Dec | AB17: Jan | AC17: Feb | AD17: Mar | AE17: Apr | AF17: May | AG17: Jun | AH17: Jul | AI17: Aug | AJ17: Sep | AK17: Oct | AL17: Nov | AM17: Dec | AN17: Jan | AO17: Feb | AP17: Mar | AQ17: Apr | AR17: May | AS17: Jun | AT17: Jul | AU17: Aug | AV17: Sep | AW17: Oct | AX17: Nov | AY17: Dec | AZ17: Jan | BA17: Feb | BB17: Mar | BC17: Apr | BD17: May | BE17: Jun | BF17: Jul | BG17: Aug | BH17: Sep | BI17: Oct | BJ17: Nov | BK17: Dec
A19: 3. FINANCIALS AS IS
A20: Revenue | B20: млн ₽ | D20: ='Cost assumptions'!D28/1000000 -> 20.454545 | E20: ='Cost assumptions'!E28/1000000 -> 41.043017 | F20: ='Cost assumptions'!F28/1000000 -> 32.941905 | G20: ='Cost assumptions'!G28/1000000 -> 33.049748 | H20: ='Cost assumptions'!H28/1000000 -> 33.157944 | I20: ='Cost assumptions'!I28/1000000 -> 33.266495 | J20: ='Cost assumptions'!J28/1000000 -> 33.3754 | K20: ='Cost assumptions'!K28/1000000 -> 33.484663 | ... BK20: ='Cost assumptions'!BK28/1000000 -> 47.625365 | BL20: =SUM(D20:O20) -> 409.36014 | BM20: =SUM(P20:AA20) -> 412.94306 | BN20: =SUM(AB20:AM20) -> 429.46078 | BO20: =SUM(AN20:AY20) -> 446.63921 | BP20: =SUM(AZ20:BK20) -> 464.50478
A21: CoS | B21: млн ₽ | D21: =-'Cost assumptions'!D29/1000000 -> -0.40909091 | E21: =-'Cost assumptions'!E29/1000000 -> -0.82086033 | F21: =-'Cost assumptions'!F29/1000000 -> -0.65883809 | G21: =-'Cost assumptions'!G29/1000000 -> -0.66099496 | H21: =-'Cost assumptions'!H29/1000000 -> -0.66315888 | I21: =-'Cost assumptions'!I29/1000000 -> -0.66532989 | J21: =-'Cost assumptions'!J29/1000000 -> -0.66750801 | K21: =-'Cost assumptions'!K29/1000000 -> -0.66969326 | ... BK21: =-'Cost assumptions'!BK29/1000000 -> -0.95250729 | BL21: =SUM(D21:O21) -> -8.1872029 | BM21: =SUM(P21:AA21) -> -8.2588611 | BN21: =SUM(AB21:AM21) -> -8.5892156 | BO21: =SUM(AN21:AY21) -> -8.9327842 | BP21: =SUM(AZ21:BK21) -> -9.2900956
A22: Staff costs | B22: млн ₽ | D22: =-'Cost assumptions'!D30/1000000 -> -7 | E22: =-'Cost assumptions'!E30/1000000 -> -7 | F22: =-'Cost assumptions'!F30/1000000 -> -7 | G22: =-'Cost assumptions'!G30/1000000 -> -7 | H22: =-'Cost assumptions'!H30/1000000 -> -7 | I22: =-'Cost assumptions'!I30/1000000 -> -7 | J22: =-'Cost assumptions'!J30/1000000 -> -7 | K22: =-'Cost assumptions'!K30/1000000 -> -7 | ... BK22: =-'Cost assumptions'!BK30/1000000 -> -9.1755721 | BL22: =SUM(D22:O22) -> -84 | BM22: =SUM(P22:AA22) -> -89.88 | BN22: =SUM(AB22:AM22) -> -96.1716 | BO22: =SUM(AN22:AY22) -> -102.90361 | BP22: =SUM(AZ22:BK22) -> -110.10686
A23: Marketing | B23: млн ₽ | D23: =-'Cost assumptions'!D31/1000000 -> -1.0227273 | E23: =-'Cost assumptions'!E31/1000000 -> -2.0521508 | F23: =-'Cost assumptions'!F31/1000000 -> -1.6470952 | G23: =-'Cost assumptions'!G31/1000000 -> -1.6524874 | H23: =-'Cost assumptions'!H31/1000000 -> -1.6578972 | I23: =-'Cost assumptions'!I31/1000000 -> -1.6633247 | J23: =-'Cost assumptions'!J31/1000000 -> -1.66877 | K23: =-'Cost assumptions'!K31/1000000 -> -1.6742331 | ... BK23: =-'Cost assumptions'!BK31/1000000 -> -2.3812682 | BL23: =SUM(D23:O23) -> -20.468007 | BM23: =SUM(P23:AA23) -> -20.647153 | BN23: =SUM(AB23:AM23) -> -21.473039 | BO23: =SUM(AN23:AY23) -> -22.33196 | BP23: =SUM(AZ23:BK23) -> -23.225239
A24: Consulting | B24: млн ₽ | D24: 0 | E24: 0 | F24: 0 | G24: 0 | H24: 0 | I24: 0 | J24: 0 | K24: 0 | L24: 0 | M24: 0 | N24: 0 | O24: 0 | P24: 0 | Q24: 0 | R24: 0 | S24: 0 | T24: 0 | U24: 0 | V24: 0 | W24: 0 | X24: 0 | Y24: 0 | Z24: 0 | AA24: 0 | AB24: 0 | AC24: 0 | AD24: 0 | AE24: 0 | AF24: 0 | AG24: 0 | AH24: 0 | AI24: 0 | AJ24: 0 | AK24: 0 | AL24: 0 | AM24: 0 | AN24: 0 | AO24: 0 | AP24: 0 | AQ24: 0 | AR24: 0 | AS24: 0 | AT24: 0 | AU24: 0 | AV24: 0 | AW24: 0 | AX24: 0 | AY24: 0 | AZ24: 0 | BA24: 0 | BB24: 0 | BC24: 0 | BD24: 0 | BE24: 0 | BF24: 0 | BG24: 0 | BH24: 0 | BI24: 0 | BJ24: 0 | BK24: 0 | BL24: =SUM(D24:O24) -> 0 | BM24: =SUM(P24:AA24) -> 0 | BN24: =SUM(AB24:AM24) -> 0 | BO24: =SUM(AN24:AY24) -> 0 | BP24: =SUM(AZ24:BK24) -> 0
A25: IT Costs | B25: млн ₽ | D25: =-'Cost assumptions'!D32/1000000 -> -0.25 | E25: =-'Cost assumptions'!E32/1000000 -> -0.25 | F25: =-'Cost assumptions'!F32/1000000 -> -0.25 | G25: =-'Cost assumptions'!G32/1000000 -> -0.25 | H25: =-'Cost assumptions'!H32/1000000 -> -0.25 | I25: =-'Cost assumptions'!I32/1000000 -> -0.25 | J25: =-'Cost assumptions'!J32/1000000 -> -0.25 | K25: =-'Cost assumptions'!K32/1000000 -> -0.25 | ... BK25: =-'Cost assumptions'!BK32/1000000 -> -0.25 | BL25: =SUM(D25:O25) -> -3 | BM25: =SUM(P25:AA25) -> -3 | BN25: =SUM(AB25:AM25) -> -3 | BO25: =SUM(AN25:AY25) -> -3 | BP25: =SUM(AZ25:BK25) -> -3
A26: G&A Costs | B26: млн ₽ | D26: =-'Cost assumptions'!D33/1000000 -> -0.35 | E26: =-'Cost assumptions'!E33/1000000 -> -0.35 | F26: =-'Cost assumptions'!F33/1000000 -> -0.35 | G26: =-'Cost assumptions'!G33/1000000 -> -0.35 | H26: =-'Cost assumptions'!H33/1000000 -> -0.35 | I26: =-'Cost assumptions'!I33/1000000 -> -0.35 | J26: =-'Cost assumptions'!J33/1000000 -> -0.35 | K26: =-'Cost assumptions'!K33/1000000 -> -0.35 | ... BK26: =-'Cost assumptions'!BK33/1000000 -> -0.4587786 | BL26: =SUM(D26:O26) -> -4.2 | BM26: =SUM(P26:AA26) -> -4.494 | BN26: =SUM(AB26:AM26) -> -4.80858 | BO26: =SUM(AN26:AY26) -> -5.1451806 | BP26: =SUM(AZ26:BK26) -> -5.5053432
A27: Other Costs | B27: млн ₽ | D27: 0 | E27: 0 | F27: 0 | G27: 0 | H27: 0 | I27: 0 | J27: 0 | K27: 0 | L27: 0 | M27: 0 | N27: 0 | O27: 0 | P27: 0 | Q27: 0 | R27: 0 | S27: 0 | T27: 0 | U27: 0 | V27: 0 | W27: 0 | X27: 0 | Y27: 0 | Z27: 0 | AA27: 0 | AB27: 0 | AC27: 0 | AD27: 0 | AE27: 0 | AF27: 0 | AG27: 0 | AH27: 0 | AI27: 0 | AJ27: 0 | AK27: 0 | AL27: 0 | AM27: 0 | AN27: 0 | AO27: 0 | AP27: 0 | AQ27: 0 | AR27: 0 | AS27: 0 | AT27: 0 | AU27: 0 | AV27: 0 | AW27: 0 | AX27: 0 | AY27: 0 | AZ27: 0 | BA27: 0 | BB27: 0 | BC27: 0 | BD27: 0 | BE27: 0 | BF27: 0 | BG27: 0 | BH27: 0 | BI27: 0 | BJ27: 0 | BK27: 0 | BL27: =SUM(D27:O27) -> 0 | BM27: =SUM(P27:AA27) -> 0 | BN27: =SUM(AB27:AM27) -> 0 | BO27: =SUM(AN27:AY27) -> 0 | BP27: =SUM(AZ27:BK27) -> 0
A28: EBITDA | B28: млн ₽ | D28: =D20+SUM(D21:D27) -> 11.422727 | E28: =E20+SUM(E21:E27) -> 30.570005 | F28: =F20+SUM(F21:F27) -> 23.035971 | G28: =G20+SUM(G21:G27) -> 23.136266 | H28: =H20+SUM(H21:H27) -> 23.236888 | I28: =I20+SUM(I21:I27) -> 23.33784 | J28: =J20+SUM(J21:J27) -> 23.439122 | K28: =K20+SUM(K21:K27) -> 23.540736 | ... BK28: =BK20+SUM(BK21:BK27) -> 34.407238 | BL28: =SUM(D28:O28) -> 289.50493 | BM28: =SUM(P28:AA28) -> 286.66304 | BN28: =SUM(AB28:AM28) -> 295.41834 | BO28: =SUM(AN28:AY28) -> 304.32567 | BP28: =SUM(AZ28:BK28) -> 313.37724
A29: EBITDA margin | B29: % | D29: =IFERROR(D28/D20,0) -> 0.55844444 | E29: =IFERROR(E28/E20,0) -> 0.74482843 | F29: =IFERROR(F28/F20,0) -> 0.69929081 | G29: =IFERROR(G28/G20,0) -> 0.70004363 | H29: =IFERROR(H28/H20,0) -> 0.70079399 | I29: =IFERROR(I28/I20,0) -> 0.7015419 | J29: =IFERROR(J28/J20,0) -> 0.70228738 | K29: =IFERROR(K28/K20,0) -> 0.70303042 | ... BP29: =IFERROR(BP28/BP20,0) -> 0.67464803
A30: Income Tax | B30: млн ₽ | D30: =-MAX(D28,0)*D12 -> -0.57113636 | E30: =-MAX(E28,0)*E12 -> -1.5285003 | F30: =-MAX(F28,0)*F12 -> -1.1517986 | G30: =-MAX(G28,0)*G12 -> -1.1568133 | H30: =-MAX(H28,0)*H12 -> -1.1618444 | I30: =-MAX(I28,0)*I12 -> -1.166892 | J30: =-MAX(J28,0)*J12 -> -1.1719561 | K30: =-MAX(K28,0)*K12 -> -1.1770368 | ... BK30: =-MAX(BK28,0)*BK12 -> -1.7203619 | BL30: =SUM(D30:O30) -> -14.475247 | BM30: =SUM(P30:AA30) -> -14.333152 | BN30: =SUM(AB30:AM30) -> -14.770917 | BO30: =SUM(AN30:AY30) -> -15.216284 | BP30: =SUM(AZ30:BK30) -> -15.668862
A31: NOPAT (EBITDA - Tax) | B31: млн ₽ | D31: =D28+D30 -> 10.851591 | E31: =E28+E30 -> 29.041505 | F31: =F28+F30 -> 21.884173 | G31: =G28+G30 -> 21.979452 | H31: =H28+H30 -> 22.075044 | I31: =I28+I30 -> 22.170948 | J31: =J28+J30 -> 22.267166 | K31: =K28+K30 -> 22.3637 | ... BK31: =BK28+BK30 -> 32.686876 | BL31: =SUM(D31:O31) -> 275.02969 | BM31: =SUM(P31:AA31) -> 272.32989 | BN31: =SUM(AB31:AM31) -> 280.64743 | BO31: =SUM(AN31:AY31) -> 289.10939 | BP31: =SUM(AZ31:BK31) -> 297.70837
A32: AR (упрощение: 60 дней оборачиваемости от Revenue) | B32: млн ₽ | D32: =D20*2 -> 40.909091 | E32: =E20*2 -> 82.086033 | F32: =F20*2 -> 65.883809 | G32: =G20*2 -> 66.099496 | H32: =H20*2 -> 66.315888 | I32: =I20*2 -> 66.532989 | J32: =J20*2 -> 66.750801 | K32: =K20*2 -> 66.969326 | ... BK32: =BK20*2 -> 95.250729 | BL32: =O32 -> 81.420722 | BM32: =AA32 -> 84.677551 | BN32: =AM32 -> 88.064653 | BO32: =AY32 -> 91.58724 | BP32: =BK32 -> 95.250729
A33: AP (60 дней оборачиваемости от затрат) | B33: млн ₽ | D33: =(D21+D23+D25+D26)*2 -> -4.0636364 | E33: =(E21+E23+E25+E26)*2 -> -6.9460223 | F33: =(F21+F23+F25+F26)*2 -> -5.8118666 | G33: =(G21+G23+G25+G26)*2 -> -5.8269647 | H33: =(H21+H23+H25+H26)*2 -> -5.8421122 | I33: =(I21+I23+I25+I26)*2 -> -5.8573092 | J33: =(J21+J23+J25+J26)*2 -> -5.8725561 | K33: =(K21+K23+K25+K26)*2 -> -5.8878528 | ... BK33: =(BK21+BK23+BK25+BK26)*2 -> -8.0851082 | BL33: =O33 -> -6.8994506 | BM33: =AA33 -> -7.1764286 | BN33: =AM33 -> -7.4659557 | BO33: =AY33 -> -7.7686369 | BP33: =BK33 -> -8.0851082
A34: NWC = AR + AP | B34: млн ₽ | D34: =D32+D33 -> 36.845455 | E34: =E32+E33 -> 75.140011 | F34: =F32+F33 -> 60.071943 | G34: =G32+G33 -> 60.272531 | H34: =H32+H33 -> 60.473776 | I34: =I32+I33 -> 60.67568 | J34: =J32+J33 -> 60.878245 | K34: =K32+K33 -> 61.081473 | ... BK34: =BK32+BK33 -> 87.165621 | BL34: =O34 -> 74.521272 | BM34: =AA34 -> 77.501123 | BN34: =AM34 -> 80.598698 | BO34: =AY34 -> 83.818603 | BP34: =BK34 -> 87.165621
A35: Change in NWC | B35: млн ₽ | D35: =-D34 -> -36.845455 | E35: =-(E34-D34) -> -38.294556 | F35: =-(F34-E34) -> 15.068068 | G35: =-(G34-F34) -> -0.2005884 | H35: =-(H34-G34) -> -0.20124507 | I35: =-(I34-H34) -> -0.20190389 | J35: =-(J34-I34) -> -0.20256488 | K35: =-(K34-J34) -> -0.20322802 | L35: =-(L34-K34) -> -0.20389334 | ... BK35: =-(BK34-BJ34) -> -0.28905199 | BL35: =-BL34 -> -74.521272 | BM35: =-(BM34-BL34) -> -2.9798509 | BN35: =-(BN34-BM34) -> -3.0975749 | BO35: =-(BO34-BN34) -> -3.219905 | BP35: =-(BP34-BO34) -> -3.3470182
A36: FCF (Free Cash Flow) | B36: млн ₽ | D36: =D31+D35 -> -25.993864 | E36: =E31+E35 -> -9.2530512 | F36: =F31+F35 -> 36.952241 | G36: =G31+G35 -> 21.778864 | H36: =H31+H35 -> 21.873799 | I36: =I31+I35 -> 21.969044 | J36: =J31+J35 -> 22.064601 | K36: =K31+K35 -> 22.160472 | ... BP36: =BP31+BP35 -> 294.36136
A38: 4. FINANCIALS INCREMENT (эффект инициативы)
A39: Revenue | B39: млн ₽ | D39: ='Cost assumptions'!D39/1000000 -> 0 | E39: ='Cost assumptions'!E39/1000000 -> 0 | F39: ='Cost assumptions'!F39/1000000 -> 0.15844522 | G39: ='Cost assumptions'!G39/1000000 -> 0.27819143 | H39: ='Cost assumptions'!H39/1000000 -> 0.49853749 | I39: ='Cost assumptions'!I39/1000000 -> 0.74955597 | J39: ='Cost assumptions'!J39/1000000 -> 1.0177593 | K39: ='Cost assumptions'!K39/1000000 -> 1.3382381 | ... BK39: ='Cost assumptions'!BK39/1000000 -> 3.4122621 | BL39: =SUM(D39:O39) -> 12.39892 | BM39: =SUM(P39:AA39) -> 29.299167 | BN39: =SUM(AB39:AM39) -> 30.769894 | BO39: =SUM(AN39:AY39) -> 32.000806 | BP39: =SUM(AZ39:BK39) -> 33.280838
A40: CoS | B40: млн ₽ | D40: =-'Cost assumptions'!D40/1000000 -> 0 | E40: =-'Cost assumptions'!E40/1000000 -> 0 | F40: =-'Cost assumptions'!F40/1000000 -> -0.0063378089 | G40: =-'Cost assumptions'!G40/1000000 -> -0.011127657 | H40: =-'Cost assumptions'!H40/1000000 -> -0.019941499 | I40: =-'Cost assumptions'!I40/1000000 -> -0.029982239 | J40: =-'Cost assumptions'!J40/1000000 -> -0.040710371 | K40: =-'Cost assumptions'!K40/1000000 -> -0.053529525 | ... BK40: =-'Cost assumptions'!BK40/1000000 -> -0.13649048 | BL40: =SUM(D40:O40) -> -0.4959568 | BM40: =SUM(P40:AA40) -> -1.1719667 | BN40: =SUM(AB40:AM40) -> -1.2307957 | BO40: =SUM(AN40:AY40) -> -1.2800322 | BP40: =SUM(AZ40:BK40) -> -1.3312335
A41: Staff costs | B41: млн ₽ | D41: =-'Cost assumptions'!D41/1000000 -> -1.212652 | E41: =-'Cost assumptions'!E41/1000000 -> -1.212652 | F41: =-'Cost assumptions'!F41/1000000 -> -1.239552 | G41: =-'Cost assumptions'!G41/1000000 -> -1.239552 | H41: =-'Cost assumptions'!H41/1000000 -> -1.609696 | I41: =-'Cost assumptions'!I41/1000000 -> -1.532224 | J41: =-'Cost assumptions'!J41/1000000 -> -1.532224 | K41: =-'Cost assumptions'!K41/1000000 -> -0.58642 | ... BK41: =-'Cost assumptions'!BK41/1000000 -> -0.34414163 | BL41: =SUM(D41:O41) -> -12.510652 | BM41: =SUM(P41:AA41) -> -3.371065 | BN41: =SUM(AB41:AM41) -> -3.6070395 | BO41: =SUM(AN41:AY41) -> -3.8595323 | BP41: =SUM(AZ41:BK41) -> -4.1296995
A42: Marketing | B42: млн ₽ | D42: =-'Cost assumptions'!D42/1000000 -> 0 | E42: =-'Cost assumptions'!E42/1000000 -> 0 | F42: =-'Cost assumptions'!F42/1000000 -> 0 | G42: =-'Cost assumptions'!G42/1000000 -> 0 | H42: =-'Cost assumptions'!H42/1000000 -> 0 | I42: =-'Cost assumptions'!I42/1000000 -> 0 | J42: =-'Cost assumptions'!J42/1000000 -> 0 | K42: =-'Cost assumptions'!K42/1000000 -> -0.33333333 | ... BK42: =-'Cost assumptions'!BK42/1000000 -> -0.25 | BL42: =SUM(D42:O42) -> -1.6666667 | BM42: =SUM(P42:AA42) -> -3.5833333 | BN42: =SUM(AB42:AM42) -> -3 | BO42: =SUM(AN42:AY42) -> -3 | BP42: =SUM(AZ42:BK42) -> -3
A43: Consulting | B43: млн ₽ | D43: 0 | E43: 0 | F43: 0 | G43: 0 | H43: 0 | I43: 0 | J43: 0 | K43: 0 | L43: 0 | M43: 0 | N43: 0 | O43: 0 | P43: 0 | Q43: 0 | R43: 0 | S43: 0 | T43: 0 | U43: 0 | V43: 0 | W43: 0 | X43: 0 | Y43: 0 | Z43: 0 | AA43: 0 | AB43: 0 | AC43: 0 | AD43: 0 | AE43: 0 | AF43: 0 | AG43: 0 | AH43: 0 | AI43: 0 | AJ43: 0 | AK43: 0 | AL43: 0 | AM43: 0 | AN43: 0 | AO43: 0 | AP43: 0 | AQ43: 0 | AR43: 0 | AS43: 0 | AT43: 0 | AU43: 0 | AV43: 0 | AW43: 0 | AX43: 0 | AY43: 0 | AZ43: 0 | BA43: 0 | BB43: 0 | BC43: 0 | BD43: 0 | BE43: 0 | BF43: 0 | BG43: 0 | BH43: 0 | BI43: 0 | BJ43: 0 | BK43: 0 | BL43: =SUM(D43:O43) -> 0 | BM43: =SUM(P43:AA43) -> 0 | BN43: =SUM(AB43:AM43) -> 0 | BO43: =SUM(AN43:AY43) -> 0 | BP43: =SUM(AZ43:BK43) -> 0
A44: IT Costs | B44: млн ₽ | D44: =-'Cost assumptions'!D43/1000000 -> -0.125 | E44: =-'Cost assumptions'!E43/1000000 -> -0.125 | F44: =-'Cost assumptions'!F43/1000000 -> -0.825 | G44: =-'Cost assumptions'!G43/1000000 -> -0.125 | H44: =-'Cost assumptions'!H43/1000000 -> -0.125 | I44: =-'Cost assumptions'!I43/1000000 -> -0.125 | J44: =-'Cost assumptions'!J43/1000000 -> -0.125 | K44: =-'Cost assumptions'!K43/1000000 -> -0.425 | ... BK44: =-'Cost assumptions'!BK43/1000000 -> -0.125 | BL44: =SUM(D44:O44) -> -2.5 | BM44: =SUM(P44:AA44) -> -2.1 | BN44: =SUM(AB44:AM44) -> -1.5 | BO44: =SUM(AN44:AY44) -> -1.5 | BP44: =SUM(AZ44:BK44) -> -1.5
...

Sheet Команда и TtM
A1: Команда и Time-to-Market (TtM)
A2: Инициатива: 3 гипотезы из ДЗ2, реализуемые волнами по приоритету (от high confidence к low)
A4: 1. Тарифная сетка
A5: Роль | B5: Уровень | C5: Salary gross, ₽/мес | D5: Налоги (×k) | E5: Cost ₽/мес (с налогами) | F5: Cost млн ₽/мес | G5: Источник
A6: Product Manager | B6: Senior | C6: 250000 | D6: 1.076 | E6: =C6*D6 -> 269000 | F6: =E6/1000000 -> 0.269
A7: UX Designer | B7: Middle+ | C7: 180000 | D7: 1.076 | E7: =C7*D7 -> 193680 | F7: =E7/1000000 -> 0.19368
A8: Data Analyst | B8: Middle+ | C8: 180000 | D8: 1.076 | E8: =C8*D8 -> 193680 | F8: =E8/1000000 -> 0.19368
A9: ML Engineer | B9: Middle+ | C9: 280000 | D9: 1.076 | E9: =C9*D9 -> 301280 | F9: =E9/1000000 -> 0.30128
A10: Backend Engineer | B10: Middle+ | C10: 250000 | D10: 1.076 | E10: =C10*D10 -> 269000 | F10: =E10/1000000 -> 0.269
A11: Frontend Engineer | B11: Middle | C11: 200000 | D11: 1.076 | E11: =C11*D11 -> 215200 | F11: =E11/1000000 -> 0.2152
A12: QA Engineer | B12: Middle | C12: 150000 | D12: 1.076 | E12: =C12*D12 -> 161400 | F12: =E12/1000000 -> 0.1614
A13: DevOps Engineer | B13: Middle+ | C13: 220000 | D13: 1.076 | E13: =C13*D13 -> 236720 | F13: =E13/1000000 -> 0.23672
A15: Страховые взносы 7,6% - льгота для IT-аккредитованных компаний (Avito аккредитована Минцифры России). Состав: ПФР 6% + ОМС 0,1% + ФСС 1,5%. НК РФ ст. 427 п. 1 пп. 3, ФЗ-321 от 14.07.2022. Бессрочная льгота для tech-сектора. Базовая ставка 30,2% применялась бы для не-IT.
A16: Налог на прибыль для IT-аккредитованных: 0% (2025), 5% (2026-2030). Действует до 31.12.2030 (ст. 284 п. 1.15 НК РФ). В модели в PnL уже учтено: 0% в 2026, 5% с 2027.
A17: 2. Roadmap волн инициативы
A18: Wave | B18: Гипотеза (из ДЗ2) | C18: Confidence | D18: Discovery | E18: Development | F18: Launch (полный) | G18: Базовая команда
A19: Wave 1 | B19: Алгоритм персонализир. рекомендаций для селлеров (ARPPU +10%) | C19: 0.75 | D19: мес 1 (Discovery+спека) | E19: мес 1-2 (Dev) | F19: мес 3 (Launch) | G19: PM, ML, BE, FE, Data, QA
A20: Wave 2 | B20: Индикатор соответствия цены рынку (ARPPU +5%) | C20: 0.6 | D20: мес 2 (параллельно с W1 Dev) | E20: мес 3-4 (Dev) | F20: мес 5 (Launch) | G20: PM, BE, FE, ML, QA
A21: Wave 3 | B21: Видео в карточках + лента "Истории" (MAU +3%) | C21: 0.4 | D21: мес 5 (Discovery) | E21: мес 6-7 (Dev, видео-инфра) | F21: мес 8 (Launch) | G21: PM, UX, BE, FE, DevOps, ML, QA
A23: TtM до полного запуска всех 3 волн: | B23: 8 | C23: мес (без буфера)
A24: Буфер на риски задержек: | B24: 0.2
A25: TtM с буфером: | B25: =B23*(1+B24) -> 9.6 | C25: ≈ 10 мес до полного релиза всех 3 волн
A26: TtM первой волны (Wave 1) до релиза: | B26: 3 | C26: мес - алгоритм рекомендаций (на готовой ML-платформе Avito)
A28: 3. Распределение FTE по ролям × месяцам (5 лет, помесячно)
A29: Логика: фичи строятся на готовой инфраструктуре Avito (ML-платформа, CDN, A/B framework). TtM компактный за счёт переиспользования существующих компонентов. После релиза каждой волны команда переходит в Support (минимальный maintenance).
A30: Роль | B30: Salary ref | C30: Unit | D30: 2026 | E30: 2026 | F30: 2026 | G30: 2026 | H30: 2026 | I30: 2026 | J30: 2026 | K30: 2026 | L30: 2026 | M30: 2026 | N30: 2026 | O30: 2026 | P30: 2027 | Q30: 2027 | R30: 2027 | S30: 2027 | T30: 2027 | U30: 2027 | V30: 2027 | W30: 2027 | X30: 2027 | Y30: 2027 | Z30: 2027 | AA30: 2027 | AB30: 2028 | AC30: 2028 | AD30: 2028 | AE30: 2028 | AF30: 2028 | AG30: 2028 | AH30: 2028 | AI30: 2028 | AJ30: 2028 | AK30: 2028 | AL30: 2028 | AM30: 2028 | AN30: 2029 | AO30: 2029 | AP30: 2029 | AQ30: 2029 | AR30: 2029 | AS30: 2029 | AT30: 2029 | AU30: 2029 | AV30: 2029 | AW30: 2029 | AX30: 2029 | AY30: 2029 | AZ30: 2030 | BA30: 2030 | BB30: 2030 | BC30: 2030 | BD30: 2030 | BE30: 2030 | BF30: 2030 | BG30: 2030 | BH30: 2030 | BI30: 2030 | BJ30: 2030 | BK30: 2030 | BL30: 2026 Total | BM30: 2027 Total | BN30: 2028 Total | BO30: 2029 Total | BP30: 2030 Total
D31: Jan | E31: Feb | F31: Mar | G31: Apr | H31: May | I31: Jun | J31: Jul | K31: Aug | L31: Sep | M31: Oct | N31: Nov | O31: Dec | P31: Jan | Q31: Feb | R31: Mar | S31: Apr | T31: May | U31: Jun | V31: Jul | W31: Aug | X31: Sep | Y31: Oct | Z31: Nov | AA31: Dec | AB31: Jan | AC31: Feb | AD31: Mar | AE31: Apr | AF31: May | AG31: Jun | AH31: Jul | AI31: Aug | AJ31: Sep | AK31: Oct | AL31: Nov | AM31: Dec | AN31: Jan | AO31: Feb | AP31: Mar | AQ31: Apr | AR31: May | AS31: Jun | AT31: Jul | AU31: Aug | AV31: Sep | AW31: Oct | AX31: Nov | AY31: Dec | AZ31: Jan | BA31: Feb | BB31: Mar | BC31: Apr | BD31: May | BE31: Jun | BF31: Jul | BG31: Aug | BH31: Sep | BI31: Oct | BJ31: Nov | BK31: Dec
A32: PM | B32: =E6 -> 269000 | C32: FTE | D32: 1 | E32: 1 | F32: 1 | G32: 1 | H32: 1 | I32: 1 | J32: 1 | K32: 0.3 | L32: 0.3 | M32: 0.3 | N32: 0.3 | O32: 0.3 | P32: 0.1 | Q32: 0.1 | R32: 0.1 | S32: 0.1 | T32: 0.1 | U32: 0.1 | V32: 0.1 | W32: 0.1 | X32: 0.1 | Y32: 0.1 | Z32: 0.1 | AA32: 0.1 | AB32: 0.1 | AC32: 0.1 | AD32: 0.1 | AE32: 0.1 | AF32: 0.1 | AG32: 0.1 | AH32: 0.1 | AI32: 0.1 | AJ32: 0.1 | AK32: 0.1 | AL32: 0.1 | AM32: 0.1 | AN32: 0.1 | AO32: 0.1 | AP32: 0.1 | AQ32: 0.1 | AR32: 0.1 | AS32: 0.1 | AT32: 0.1 | AU32: 0.1 | AV32: 0.1 | AW32: 0.1 | AX32: 0.1 | AY32: 0.1 | AZ32: 0.1 | BA32: 0.1 | BB32: 0.1 | BC32: 0.1 | BD32: 0.1 | BE32: 0.1 | BF32: 0.1 | BG32: 0.1 | BH32: 0.1 | BI32: 0.1 | BJ32: 0.1 | BK32: 0.1 | BL32: =AVERAGE(D32:O32) -> 0.70833333 | BM32: =AVERAGE(P32:AA32) -> 0.1 | BN32: =AVERAGE(AB32:AM32) -> 0.1 | BO32: =AVERAGE(AN32:AY32) -> 0.1 | BP32: =AVERAGE(AZ32:BK32) -> 0.1
A33: UX Designer | B33: =E7 -> 193680 | C33: FTE | D33: 0.5 | E33: 0.5 | F33: 0 | G33: 0 | H33: 0.7 | I33: 0.3 | J33: 0.3 | K33: 0.1 | L33: 0.1 | M33: 0.1 | N33: 0.1 | O33: 0.1 | P33: 0 | Q33: 0 | R33: 0 | S33: 0 | T33: 0 | U33: 0 | V33: 0 | W33: 0 | X33: 0 | Y33: 0 | Z33: 0 | AA33: 0 | AB33: 0 | AC33: 0 | AD33: 0 | AE33: 0 | AF33: 0 | AG33: 0 | AH33: 0 | AI33: 0 | AJ33: 0 | AK33: 0 | AL33: 0 | AM33: 0 | AN33: 0 | AO33: 0 | AP33: 0 | AQ33: 0 | AR33: 0 | AS33: 0 | AT33: 0 | AU33: 0 | AV33: 0 | AW33: 0 | AX33: 0 | AY33: 0 | AZ33: 0 | BA33: 0 | BB33: 0 | BC33: 0 | BD33: 0 | BE33: 0 | BF33: 0 | BG33: 0 | BH33: 0 | BI33: 0 | BJ33: 0 | BK33: 0 | BL33: =AVERAGE(D33:O33) -> 0.23333333 | BM33: =AVERAGE(P33:AA33) -> 0 | BN33: =AVERAGE(AB33:AM33) -> 0 | BO33: =AVERAGE(AN33:AY33) -> 0 | BP33: =AVERAGE(AZ33:BK33) -> 0
A34: Data Analyst | B34: =E8 -> 193680 | C34: FTE | D34: 0.5 | E34: 0.5 | F34: 0.5 | G34: 0.5 | H34: 0.5 | I34: 0.5 | J34: 0.5 | K34: 0.3 | L34: 0.3 | M34: 0.3 | N34: 0.3 | O34: 0.3 | P34: 0.2 | Q34: 0.2 | R34: 0.2 | S34: 0.2 | T34: 0.2 | U34: 0.2 | V34: 0.2 | W34: 0.2 | X34: 0.2 | Y34: 0.2 | Z34: 0.2 | AA34: 0.2 | AB34: 0.2 | AC34: 0.2 | AD34: 0.2 | AE34: 0.2 | AF34: 0.2 | AG34: 0.2 | AH34: 0.2 | AI34: 0.2 | AJ34: 0.2 | AK34: 0.2 | AL34: 0.2 | AM34: 0.2 | AN34: 0.2 | AO34: 0.2 | AP34: 0.2 | AQ34: 0.2 | AR34: 0.2 | AS34: 0.2 | AT34: 0.2 | AU34: 0.2 | AV34: 0.2 | AW34: 0.2 | AX34: 0.2 | AY34: 0.2 | AZ34: 0.2 | BA34: 0.2 | BB34: 0.2 | BC34: 0.2 | BD34: 0.2 | BE34: 0.2 | BF34: 0.2 | BG34: 0.2 | BH34: 0.2 | BI34: 0.2 | BJ34: 0.2 | BK34: 0.2 | BL34: =AVERAGE(D34:O34) -> 0.41666667 | BM34: =AVERAGE(P34:AA34) -> 0.2 | BN34: =AVERAGE(AB34:AM34) -> 0.2 | BO34: =AVERAGE(AN34:AY34) -> 0.2 | BP34: =AVERAGE(AZ34:BK34) -> 0.2
A35: ML Engineer | B35: =E9 -> 301280 | C35: FTE | D35: 1 | E35: 1 | F35: 0.5 | G35: 0.5 | H35: 0.5 | I35: 0.5 | J35: 0.5 | K35: 0.3 | L35: 0.3 | M35: 0.3 | N35: 0.3 | O35: 0.3 | P35: 0.2 | Q35: 0.2 | R35: 0.2 | S35: 0.2 | T35: 0.2 | U35: 0.2 | V35: 0.2 | W35: 0.2 | X35: 0.2 | Y35: 0.2 | Z35: 0.2 | AA35: 0.2 | AB35: 0.2 | AC35: 0.2 | AD35: 0.2 | AE35: 0.2 | AF35: 0.2 | AG35: 0.2 | AH35: 0.2 | AI35: 0.2 | AJ35: 0.2 | AK35: 0.2 | AL35: 0.2 | AM35: 0.2 | AN35: 0.2 | AO35: 0.2 | AP35: 0.2 | AQ35: 0.2 | AR35: 0.2 | AS35: 0.2 | AT35: 0.2 | AU35: 0.2 | AV35: 0.2 | AW35: 0.2 | AX35: 0.2 | AY35: 0.2 | AZ35: 0.2 | BA35: 0.2 | BB35: 0.2 | BC35: 0.2 | BD35: 0.2 | BE35: 0.2 | BF35: 0.2 | BG35: 0.2 | BH35: 0.2 | BI35: 0.2 | BJ35: 0.2 | BK35: 0.2 | BL35: =AVERAGE(D35:O35) -> 0.5 | BM35: =AVERAGE(P35:AA35) -> 0.2 | BN35: =AVERAGE(AB35:AM35) -> 0.2 | BO35: =AVERAGE(AN35:AY35) -> 0.2 | BP35: =AVERAGE(AZ35:BK35) -> 0.2
A36: Backend | B36: =E10 -> 269000 | C36: FTE | D36: 1 | E36: 1 | F36: 1.5 | G36: 1.5 | H36: 1.5 | I36: 1.5 | J36: 1.5 | K36: 0.5 | L36: 0.5 | M36: 0.5 | N36: 0.5 | O36: 0.5 | P36: 0.2 | Q36: 0.2 | R36: 0.2 | S36: 0.2 | T36: 0.2 | U36: 0.2 | V36: 0.2 | W36: 0.2 | X36: 0.2 | Y36: 0.2 | Z36: 0.2 | AA36: 0.2 | AB36: 0.2 | AC36: 0.2 | AD36: 0.2 | AE36: 0.2 | AF36: 0.2 | AG36: 0.2 | AH36: 0.2 | AI36: 0.2 | AJ36: 0.2 | AK36: 0.2 | AL36: 0.2 | AM36: 0.2 | AN36: 0.2 | AO36: 0.2 | AP36: 0.2 | AQ36: 0.2 | AR36: 0.2 | AS36: 0.2 | AT36: 0.2 | AU36: 0.2 | AV36: 0.2 | AW36: 0.2 | AX36: 0.2 | AY36: 0.2 | AZ36: 0.2 | BA36: 0.2 | BB36: 0.2 | BC36: 0.2 | BD36: 0.2 | BE36: 0.2 | BF36: 0.2 | BG36: 0.2 | BH36: 0.2 | BI36: 0.2 | BJ36: 0.2 | BK36: 0.2 | BL36: =AVERAGE(D36:O36) -> 1 | BM36: =AVERAGE(P36:AA36) -> 0.2 | BN36: =AVERAGE(AB36:AM36) -> 0.2 | BO36: =AVERAGE(AN36:AY36) -> 0.2 | BP36: =AVERAGE(AZ36:BK36) -> 0.2
A37: Frontend | B37: =E11 -> 215200 | C37: FTE | D37: 0.5 | E37: 0.5 | F37: 1 | G37: 1 | H37: 1.5 | I37: 1.5 | J37: 1.5 | K37: 0.5 | L37: 0.5 | M37: 0.5 | N37: 0.5 | O37: 0.5 | P37: 0.2 | Q37: 0.2 | R37: 0.2 | S37: 0.2 | T37: 0.2 | U37: 0.2 | V37: 0.2 | W37: 0.2 | X37: 0.2 | Y37: 0.2 | Z37: 0.2 | AA37: 0.2 | AB37: 0.2 | AC37: 0.2 | AD37: 0.2 | AE37: 0.2 | AF37: 0.2 | AG37: 0.2 | AH37: 0.2 | AI37: 0.2 | AJ37: 0.2 | AK37: 0.2 | AL37: 0.2 | AM37: 0.2 | AN37: 0.2 | AO37: 0.2 | AP37: 0.2 | AQ37: 0.2 | AR37: 0.2 | AS37: 0.2 | AT37: 0.2 | AU37: 0.2 | AV37: 0.2 | AW37: 0.2 | AX37: 0.2 | AY37: 0.2 | AZ37: 0.2 | BA37: 0.2 | BB37: 0.2 | BC37: 0.2 | BD37: 0.2 | BE37: 0.2 | BF37: 0.2 | BG37: 0.2 | BH37: 0.2 | BI37: 0.2 | BJ37: 0.2 | BK37: 0.2 | BL37: =AVERAGE(D37:O37) -> 0.83333333 | BM37: =AVERAGE(P37:AA37) -> 0.2 | BN37: =AVERAGE(AB37:AM37) -> 0.2 | BO37: =AVERAGE(AN37:AY37) -> 0.2 | BP37: =AVERAGE(AZ37:BK37) -> 0.2
A38: QA | B38: =E12 -> 161400 | C38: FTE | D38: 0.3 | E38: 0.3 | F38: 0.5 | G38: 0.5 | H38: 0.7 | I38: 0.7 | J38: 0.7 | K38: 0.3 | L38: 0.3 | M38: 0.3 | N38: 0.3 | O38: 0.3 | P38: 0.1 | Q38: 0.1 | R38: 0.1 | S38: 0.1 | T38: 0.1 | U38: 0.1 | V38: 0.1 | W38: 0.1 | X38: 0.1 | Y38: 0.1 | Z38: 0.1 | AA38: 0.1 | AB38: 0.1 | AC38: 0.1 | AD38: 0.1 | AE38: 0.1 | AF38: 0.1 | AG38: 0.1 | AH38: 0.1 | AI38: 0.1 | AJ38: 0.1 | AK38: 0.1 | AL38: 0.1 | AM38: 0.1 | AN38: 0.1 | AO38: 0.1 | AP38: 0.1 | AQ38: 0.1 | AR38: 0.1 | AS38: 0.1 | AT38: 0.1 | AU38: 0.1 | AV38: 0.1 | AW38: 0.1 | AX38: 0.1 | AY38: 0.1 | AZ38: 0.1 | BA38: 0.1 | BB38: 0.1 | BC38: 0.1 | BD38: 0.1 | BE38: 0.1 | BF38: 0.1 | BG38: 0.1 | BH38: 0.1 | BI38: 0.1 | BJ38: 0.1 | BK38: 0.1 | BL38: =AVERAGE(D38:O38) -> 0.43333333 | BM38: =AVERAGE(P38:AA38) -> 0.1 | BN38: =AVERAGE(AB38:AM38) -> 0.1 | BO38: =AVERAGE(AN38:AY38) -> 0.1 | BP38: =AVERAGE(AZ38:BK38) -> 0.1
A39: DevOps | B39: =E13 -> 236720 | C39: FTE | D39: 0.1 | E39: 0.1 | F39: 0.1 | G39: 0.1 | H39: 0.5 | I39: 0.5 | J39: 0.5 | K39: 0.2 | L39: 0.2 | M39: 0.2 | N39: 0.2 | O39: 0.2 | P39: 0.1 | Q39: 0.1 | R39: 0.1 | S39: 0.1 | T39: 0.1 | U39: 0.1 | V39: 0.1 | W39: 0.1 | X39: 0.1 | Y39: 0.1 | Z39: 0.1 | AA39: 0.1 | AB39: 0.1 | AC39: 0.1 | AD39: 0.1 | AE39: 0.1 | AF39: 0.1 | AG39: 0.1 | AH39: 0.1 | AI39: 0.1 | AJ39: 0.1 | AK39: 0.1 | AL39: 0.1 | AM39: 0.1 | AN39: 0.1 | AO39: 0.1 | AP39: 0.1 | AQ39: 0.1 | AR39: 0.1 | AS39: 0.1 | AT39: 0.1 | AU39: 0.1 | AV39: 0.1 | AW39: 0.1 | AX39: 0.1 | AY39: 0.1 | AZ39: 0.1 | BA39: 0.1 | BB39: 0.1 | BC39: 0.1 | BD39: 0.1 | BE39: 0.1 | BF39: 0.1 | BG39: 0.1 | BH39: 0.1 | BI39: 0.1 | BJ39: 0.1 | BK39: 0.1 | BL39: =AVERAGE(D39:O39) -> 0.24166667 | BM39: =AVERAGE(P39:AA39) -> 0.1 | BN39: =AVERAGE(AB39:AM39) -> 0.1 | BO39: =AVERAGE(AN39:AY39) -> 0.1 | BP39: =AVERAGE(AZ39:BK39) -> 0.1
A40: Σ FTE команды | D40: =SUM(D32:D39) -> 4.9 | E40: =SUM(E32:E39) -> 4.9 | F40: =SUM(F32:F39) -> 5.1 | G40: =SUM(G32:G39) -> 5.1 | H40: =SUM(H32:H39) -> 6.9 | I40: =SUM(I32:I39) -> 6.5 | J40: =SUM(J32:J39) -> 6.5 | K40: =SUM(K32:K39) -> 2.5 | ... BK40: =SUM(BK32:BK39) -> 1.1 | BL40: =AVERAGE(D40:O40) -> 4.3666667 | BM40: =AVERAGE(P40:AA40) -> 1.1 | BN40: =AVERAGE(AB40:AM40) -> 1.1 | BO40: =AVERAGE(AN40:AY40) -> 1.1 | BP40: =AVERAGE(AZ40:BK40) -> 1.1
A42: 4. Стоимость персонала (₽, с налогами и индексацией ЗП 7% г/г)
A43: Индексация ЗП (×) | B43: 0.07 | C43: г/г | D43: =(1+$B$43)^0 -> 1 | E43: =(1+$B$43)^0 -> 1 | F43: =(1+$B$43)^0 -> 1 | G43: =(1+$B$43)^0 -> 1 | H43: =(1+$B$43)^0 -> 1 | I43: =(1+$B$43)^0 -> 1 | J43: =(1+$B$43)^0 -> 1 | K43: =(1+$B$43)^0 -> 1 | ... O43: =(1+$B$43)^0 -> 1 | P43: =(1+$B$43)^1 -> 1.07 | Q43: =(1+$B$43)^1 -> 1.07 | R43: =(1+$B$43)^1 -> 1.07 | S43: =(1+$B$43)^1 -> 1.07 | T43: =(1+$B$43)^1 -> 1.07 | U43: =(1+$B$43)^1 -> 1.07 | V43: =(1+$B$43)^1 -> 1.07 | W43: =(1+$B$43)^1 -> 1.07 | ... AA43: =(1+$B$43)^1 -> 1.07 | AB43: =(1+$B$43)^2 -> 1.1449 | AC43: =(1+$B$43)^2 -> 1.1449 | AD43: =(1+$B$43)^2 -> 1.1449 | AE43: =(1+$B$43)^2 -> 1.1449 | AF43: =(1+$B$43)^2 -> 1.1449 | AG43: =(1+$B$43)^2 -> 1.1449 | AH43: =(1+$B$43)^2 -> 1.1449 | AI43: =(1+$B$43)^2 -> 1.1449 | ... AM43: =(1+$B$43)^2 -> 1.1449 | AN43: =(1+$B$43)^3 -> 1.225043 | AO43: =(1+$B$43)^3 -> 1.225043 | AP43: =(1+$B$43)^3 -> 1.225043 | AQ43: =(1+$B$43)^3 -> 1.225043 | AR43: =(1+$B$43)^3 -> 1.225043 | AS43: =(1+$B$43)^3 -> 1.225043 | AT43: =(1+$B$43)^3 -> 1.225043 | AU43: =(1+$B$43)^3 -> 1.225043 | ... AY43: =(1+$B$43)^3 -> 1.225043 | AZ43: =(1+$B$43)^4 -> 1.310796 | BA43: =(1+$B$43)^4 -> 1.310796 | BB43: =(1+$B$43)^4 -> 1.310796 | BC43: =(1+$B$43)^4 -> 1.310796 | BD43: =(1+$B$43)^4 -> 1.310796 | BE43: =(1+$B$43)^4 -> 1.310796 | BF43: =(1+$B$43)^4 -> 1.310796 | BG43: =(1+$B$43)^4 -> 1.310796 | ... BK43: =(1+$B$43)^4 -> 1.310796
A44: Cost PM, ₽ | D44: =D32*$E6*D43 -> 269000 | E44: =E32*$E6*E43 -> 269000 | F44: =F32*$E6*F43 -> 269000 | G44: =G32*$E6*G43 -> 269000 | H44: =H32*$E6*H43 -> 269000 | I44: =I32*$E6*I43 -> 269000 | J44: =J32*$E6*J43 -> 269000 | K44: =K32*$E6*K43 -> 80700 | ... BK44: =BK32*$E6*BK43 -> 35260.413 | BL44: =SUM(D44:O44) -> 2286500 | BM44: =SUM(P44:AA44) -> 345396 | BN44: =SUM(AB44:AM44) -> 369573.72 | BO44: =SUM(AN44:AY44) -> 395443.88 | BP44: =SUM(AZ44:BK44) -> 423124.95
A45: Cost UX Designer, ₽ | D45: =D33*$E7*D43 -> 96840 | E45: =E33*$E7*E43 -> 96840 | F45: =F33*$E7*F43 -> 0 | G45: =G33*$E7*G43 -> 0 | H45: =H33*$E7*H43 -> 135576 | I45: =I33*$E7*I43 -> 58104 | J45: =J33*$E7*J43 -> 58104 | K45: =K33*$E7*K43 -> 19368 | ... BK45: =BK33*$E7*BK43 -> 0 | BL45: =SUM(D45:O45) -> 542304 | BM45: =SUM(P45:AA45) -> 0 | BN45: =SUM(AB45:AM45) -> 0 | BO45: =SUM(AN45:AY45) -> 0 | BP45: =SUM(AZ45:BK45) -> 0
...

Sheet CashFlow
A1: CashFlow прямым методом - Increment (наша инициатива)
A2: Прямой метод: суммируем фактические денежные потоки (поступления − выплаты) по месяцам. Все суммы в млн ₽. AR=0 дней (платежи приходят сразу), AP=60 дней (платим поставщикам с задержкой).
A4: Параметры
A5: AR delay (мес) | B5: 0
A6: AP delay (мес) | B6: 2
A7: Tax payment delay (мес, после конца квартала) | B7: 1
A8: Reference: PnL!Income Tax row | B8: =12 -> 12
A9: Reference: PnL!НДС row | B9: =13 -> 13
A11: Параметр | B11: Ед. | D11: 2026 | E11: 2026 | F11: 2026 | G11: 2026 | H11: 2026 | I11: 2026 | J11: 2026 | K11: 2026 | L11: 2026 | M11: 2026 | N11: 2026 | O11: 2026 | P11: 2027 | Q11: 2027 | R11: 2027 | S11: 2027 | T11: 2027 | U11: 2027 | V11: 2027 | W11: 2027 | X11: 2027 | Y11: 2027 | Z11: 2027 | AA11: 2027 | AB11: 2028 | AC11: 2028 | AD11: 2028 | AE11: 2028 | AF11: 2028 | AG11: 2028 | AH11: 2028 | AI11: 2028 | AJ11: 2028 | AK11: 2028 | AL11: 2028 | AM11: 2028 | AN11: 2029 | AO11: 2029 | AP11: 2029 | AQ11: 2029 | AR11: 2029 | AS11: 2029 | AT11: 2029 | AU11: 2029 | AV11: 2029 | AW11: 2029 | AX11: 2029 | AY11: 2029 | AZ11: 2030 | BA11: 2030 | BB11: 2030 | BC11: 2030 | BD11: 2030 | BE11: 2030 | BF11: 2030 | BG11: 2030 | BH11: 2030 | BI11: 2030 | BJ11: 2030 | BK11: 2030 | BL11: 2026 Total | BM11: 2027 Total | BN11: 2028 Total | BO11: 2029 Total | BP11: 2030 Total
D12: Jan | E12: Feb | F12: Mar | G12: Apr | H12: May | I12: Jun | J12: Jul | K12: Aug | L12: Sep | M12: Oct | N12: Nov | O12: Dec | P12: Jan | Q12: Feb | R12: Mar | S12: Apr | T12: May | U12: Jun | V12: Jul | W12: Aug | X12: Sep | Y12: Oct | Z12: Nov | AA12: Dec | AB12: Jan | AC12: Feb | AD12: Mar | AE12: Apr | AF12: May | AG12: Jun | AH12: Jul | AI12: Aug | AJ12: Sep | AK12: Oct | AL12: Nov | AM12: Dec | AN12: Jan | AO12: Feb | AP12: Mar | AQ12: Apr | AR12: May | AS12: Jun | AT12: Jul | AU12: Aug | AV12: Sep | AW12: Oct | AX12: Nov | AY12: Dec | AZ12: Jan | BA12: Feb | BB12: Mar | BC12: Apr | BD12: May | BE12: Jun | BF12: Jul | BG12: Aug | BH12: Sep | BI12: Oct | BJ12: Nov | BK12: Dec
A14: ПОСТУПЛЕНИЯ (Increment)
A15: Revenue Increment (без НДС) | B15: млн ₽ | D15: =PnL!D39 -> 0 | E15: =PnL!E39 -> 0 | F15: =PnL!F39 -> 0.15844522 | G15: =PnL!G39 -> 0.27819143 | H15: =PnL!H39 -> 0.49853749 | I15: =PnL!I39 -> 0.74955597 | J15: =PnL!J39 -> 1.0177593 | K15: =PnL!K39 -> 1.3382381 | ... BK15: =PnL!BK39 -> 3.4122621 | BL15: =SUM(D15:O15) -> 12.39892 | BM15: =SUM(P15:AA15) -> 29.299167 | BN15: =SUM(AB15:AM15) -> 30.769894 | BO15: =SUM(AN15:AY15) -> 32.000806 | BP15: =SUM(AZ15:BK15) -> 33.280838
A16: НДС начислен с Revenue (исходящий) | B16: млн ₽ | D16: =D15*PnL!D13 -> 0 | E16: =E15*PnL!E13 -> 0 | F16: =F15*PnL!F13 -> 0.031689044 | G16: =G15*PnL!G13 -> 0.055638286 | H16: =H15*PnL!H13 -> 0.099707497 | I16: =I15*PnL!I13 -> 0.14991119 | J16: =J15*PnL!J13 -> 0.20355185 | K16: =K15*PnL!K13 -> 0.26764763 | ... BK16: =BK15*PnL!BK13 -> 0.75069767 | BL16: =SUM(D16:O16) -> 2.479784 | BM16: =SUM(P16:AA16) -> 6.4458167 | BN16: =SUM(AB16:AM16) -> 6.7693766 | BO16: =SUM(AN16:AY16) -> 7.0401773 | BP16: =SUM(AZ16:BK16) -> 7.3217844
A17: Денежные поступления (Revenue × (1+НДС), AR delay=0) | B17: млн ₽ | D17: =D15+D16 -> 0 | E17: =E15+E16 -> 0 | F17: =F15+F16 -> 0.19013427 | G17: =G15+G16 -> 0.33382972 | H17: =H15+H16 -> 0.59824498 | I17: =I15+I16 -> 0.89946716 | J17: =J15+J16 -> 1.2213111 | K17: =K15+K16 -> 1.6058858 | ... BK17: =BK15+BK16 -> 4.1629598 | BL17: =SUM(D17:O17) -> 14.878704 | BM17: =SUM(P17:AA17) -> 35.744983 | BN17: =SUM(AB17:AM17) -> 37.53927 | BO17: =SUM(AN17:AY17) -> 39.040983 | BP17: =SUM(AZ17:BK17) -> 40.602623
A19: ВЫПЛАТЫ (Increment)
A20: Выплаты по CoS (× (1+НДС), AP delay=2 мес) | B20: млн ₽ | D20: 0 | E20: 0 | F20: =-PnL!D40*(1+PnL!D13) -> 0 | G20: =-PnL!E40*(1+PnL!E13) -> 0 | H20: =-PnL!F40*(1+PnL!F13) -> 0.0076053706 | I20: =-PnL!G40*(1+PnL!G13) -> 0.013353189 | J20: =-PnL!H40*(1+PnL!H13) -> 0.023929799 | K20: =-PnL!I40*(1+PnL!I13) -> 0.035978687 | L20: =-PnL!J40*(1+PnL!J13) -> 0.048852445 | M20: =-PnL!K40*(1+PnL!K13) -> 0.06423543 | ... BK20: =-PnL!BI40*(1+PnL!BI13) -> 0.13786121 | BL20: =SUM(D20:O20) -> 0.35650889 | BM20: =SUM(P20:AA20) -> 1.3728772 | BN20: =SUM(AB20:AM20) -> 1.4897234 | BO20: =SUM(AN20:AY20) -> 1.549343 | BP20: =SUM(AZ20:BK20) -> 1.6113167
A21: Выплаты по Staff (без НДС, без задержки) | B21: млн ₽ | D21: =-PnL!D41 -> 1.212652 | E21: =-PnL!E41 -> 1.212652 | F21: =-PnL!F41 -> 1.239552 | G21: =-PnL!G41 -> 1.239552 | H21: =-PnL!H41 -> 1.609696 | I21: =-PnL!I41 -> 1.532224 | J21: =-PnL!J41 -> 1.532224 | K21: =-PnL!K41 -> 0.58642 | ... BK21: =-PnL!BK41 -> 0.34414163 | BL21: =SUM(D21:O21) -> 12.510652 | BM21: =SUM(P21:AA21) -> 3.371065 | BN21: =SUM(AB21:AM21) -> 3.6070395 | BO21: =SUM(AN21:AY21) -> 3.8595323 | BP21: =SUM(AZ21:BK21) -> 4.1296995
A22: Выплаты по Marketing (× (1+НДС), AP delay=2 мес) | B22: млн ₽ | D22: 0 | E22: 0 | F22: =-PnL!D42*(1+PnL!D13) -> 0 | G22: =-PnL!E42*(1+PnL!E13) -> 0 | H22: =-PnL!F42*(1+PnL!F13) -> 0 | I22: =-PnL!G42*(1+PnL!G13) -> 0 | J22: =-PnL!H42*(1+PnL!H13) -> 0 | K22: =-PnL!I42*(1+PnL!I13) -> 0 | L22: =-PnL!J42*(1+PnL!J13) -> 0 | M22: =-PnL!K42*(1+PnL!K13) -> 0.4 | ... BK22: =-PnL!BI42*(1+PnL!BI13) -> 0.305 | BL22: =SUM(D22:O22) -> 1.2 | BM22: =SUM(P22:AA22) -> 4.5616667 | BN22: =SUM(AB22:AM22) -> 3.66 | BO22: =SUM(AN22:AY22) -> 3.66 | BP22: =SUM(AZ22:BK22) -> 3.66
A23: Выплаты по IT (× (1+НДС), AP delay=2 мес) | B23: млн ₽ | D23: 0 | E23: 0 | F23: =-PnL!D44*(1+PnL!D13) -> 0.15 | G23: =-PnL!E44*(1+PnL!E13) -> 0.15 | H23: =-PnL!F44*(1+PnL!F13) -> 0.99 | I23: =-PnL!G44*(1+PnL!G13) -> 0.15 | J23: =-PnL!H44*(1+PnL!H13) -> 0.15 | K23: =-PnL!I44*(1+PnL!I13) -> 0.15 | L23: =-PnL!J44*(1+PnL!J13) -> 0.15 | M23: =-PnL!K44*(1+PnL!K13) -> 0.51 | ... BK23: =-PnL!BI44*(1+PnL!BI13) -> 0.1525 | BL23: =SUM(D23:O23) -> 2.7 | BM23: =SUM(P23:AA23) -> 2.557 | BN23: =SUM(AB23:AM23) -> 1.83 | BO23: =SUM(AN23:AY23) -> 1.83 | BP23: =SUM(AZ23:BK23) -> 1.83
A24: Выплаты по G&A (× (1+НДС), AP delay=2 мес) | B24: млн ₽ | D24: 0 | E24: 0 | F24: =-PnL!D45*(1+PnL!D13) -> 0.07275912 | G24: =-PnL!E45*(1+PnL!E13) -> 0.07275912 | H24: =-PnL!F45*(1+PnL!F13) -> 0.07437312 | I24: =-PnL!G45*(1+PnL!G13) -> 0.07437312 | J24: =-PnL!H45*(1+PnL!H13) -> 0.09658176 | K24: =-PnL!I45*(1+PnL!I13) -> 0.09193344 | L24: =-PnL!J45*(1+PnL!J13) -> 0.09193344 | M24: =-PnL!K45*(1+PnL!K13) -> 0.0351852 | ... BK24: =-PnL!BI45*(1+PnL!BI13) -> 0.020992639 | BL24: =SUM(D24:O24) -> 0.68026872 | BM24: =SUM(P24:AA24) -> 0.24173287 | BN24: =SUM(AB24:AM24) -> 0.21763034 | BO24: =SUM(AN24:AY24) -> 0.23286446 | BP24: =SUM(AZ24:BK24) -> 0.24916497
A25: Уплата налога на прибыль (квартально, с задержкой 1 мес) | B25: млн ₽ | D25: 0 | E25: 0 | F25: 0 | G25: =-(PnL!D49+PnL!E49+PnL!F49) -> 0 | H25: 0 | I25: 0 | J25: =-(PnL!G49+PnL!H49+PnL!I49) -> 0 | K25: 0 | L25: 0 | M25: =-(PnL!J49+PnL!K49+PnL!L49) -> 0.022371303 | N25: 0 | O25: 0 | P25: =-(PnL!M49+PnL!N49+PnL!O49) -> 0.16400707 | Q25: 0 | R25: 0 | S25: =-(PnL!P49+PnL!Q49+PnL!R49) -> 0.13972656 | T25: 0 | U25: 0 | V25: =-(PnL!S49+PnL!T49+PnL!U49) -> 0.24043916 | W25: 0 | X25: 0 | Y25: =-(PnL!V49+PnL!W49+PnL!X49) -> 0.25430207 | Z25: 0 | AA25: 0 | AB25: =-(PnL!Y49+PnL!Z49+PnL!AA49) -> 0.31074464 | AC25: 0 | AD25: 0 | AE25: =-(PnL!AB49+PnL!AC49+PnL!AD49) -> 0.20194204 | AF25: 0 | AG25: 0 | AH25: =-(PnL!AE49+PnL!AF49+PnL!AG49) -> 0.26642437 | AI25: 0 | AJ25: 0 | AK25: =-(PnL!AH49+PnL!AI49+PnL!AJ49) -> 0.27007103 | AL25: 0 | AM25: 0 | AN25: =-(PnL!AK49+PnL!AL49+PnL!AM49) -> 0.32414788 | AO25: 0 | AP25: 0 | AQ25: =-(PnL!AN49+PnL!AO49+PnL!AP49) -> 0.21085405 | AR25: 0 | AS25: 0 | AT25: =-(PnL!AQ49+PnL!AR49+PnL!AS49) -> 0.27791194 | AU25: 0 | AV25: 0 | AW25: =-(PnL!AT49+PnL!AU49+PnL!AV49) -> 0.28170372 | AX25: 0 | AY25: 0 | AZ25: =-(PnL!AW49+PnL!AX49+PnL!AY49) -> 0.33794354 | BA25: 0 | BB25: 0 | BC25: =-(PnL!AZ49+PnL!BA49+PnL!BB49) -> 0.22001852 | BD25: 0 | BE25: 0 | BF25: =-(PnL!BC49+PnL!BD49+PnL!BE49) -> 0.28975873 | BG25: 0 | BH25: 0 | BI25: =-(PnL!BF49+PnL!BG49+PnL!BH49) -> 0.29370217 | BJ25: 0 | BK25: 0 | BL25: =SUM(D25:O25) -> 0.022371303 | BM25: =SUM(P25:AA25) -> 0.79847486 | BN25: =SUM(AB25:AM25) -> 1.0491821 | BO25: =SUM(AN25:AY25) -> 1.0946176 | BP25: =SUM(AZ25:BK25) -> 1.141423
A26: Уплата НДС (NET) в бюджет (квартально) | B26: млн ₽ | D26: 0 | E26: 0 | F26: 0 | G26: 0 | H26: 0 | I26: 0 | J26: 0 | K26: 0 | L26: 0 | M26: 0 | N26: 0 | O26: 0 | P26: 0 | Q26: 0 | R26: 0 | S26: 0 | T26: 0 | U26: 0 | V26: 0 | W26: 0 | X26: 0 | Y26: 0 | Z26: 0 | AA26: 0 | AB26: 0 | AC26: 0 | AD26: 0 | AE26: 0 | AF26: 0 | AG26: 0 | AH26: 0 | AI26: 0 | AJ26: 0 | AK26: 0 | AL26: 0 | AM26: 0 | AN26: 0 | AO26: 0 | AP26: 0 | AQ26: 0 | AR26: 0 | AS26: 0 | AT26: 0 | AU26: 0 | AV26: 0 | AW26: 0 | AX26: 0 | AY26: 0 | AZ26: 0 | BA26: 0 | BB26: 0 | BC26: 0 | BD26: 0 | BE26: 0 | BF26: 0 | BG26: 0 | BH26: 0 | BI26: 0 | BJ26: 0 | BK26: 0 | BL26: =SUM(D26:O26) -> 0 | BM26: =SUM(P26:AA26) -> 0 | BN26: =SUM(AB26:AM26) -> 0 | BO26: =SUM(AN26:AY26) -> 0 | BP26: =SUM(AZ26:BK26) -> 0
A27: Σ Выплаты | B27: млн ₽ | D27: =SUM(D20:D26) -> 1.212652 | E27: =SUM(E20:E26) -> 1.212652 | F27: =SUM(F20:F26) -> 1.4623111 | G27: =SUM(G20:G26) -> 1.4623111 | H27: =SUM(H20:H26) -> 2.6816745 | I27: =SUM(I20:I26) -> 1.7699503 | J27: =SUM(J20:J26) -> 1.8027356 | K27: =SUM(K20:K26) -> 0.86433213 | ... BK27: =SUM(BK20:BK26) -> 0.96049547 | BL27: =SUM(D27:O27) -> 17.469801 | BM27: =SUM(P27:AA27) -> 12.902817 | BN27: =SUM(AB27:AM27) -> 11.853575 | BO27: =SUM(AN27:AY27) -> 12.226357 | BP27: =SUM(AZ27:BK27) -> 12.621604
A29: Operating CashFlow (поступления − выплаты) | B29: млн ₽ | D29: =D17-D27 -> -1.212652 | E29: =E17-E27 -> -1.212652 | F29: =F17-F27 -> -1.2721769 | G29: =G17-G27 -> -1.1284814 | H29: =H17-H27 -> -2.0834295 | I29: =I17-I27 -> -0.87048314 | J29: =J17-J27 -> -0.58142443 | K29: =K17-K27 -> 0.74155364 | ... BK29: =BK17-BK27 -> 3.2024643 | BL29: =SUM(D29:O29) -> -2.5910968 | BM29: =SUM(P29:AA29) -> 22.842167 | BN29: =SUM(AB29:AM29) -> 25.685695 | BO29: =SUM(AN29:AY29) -> 26.814626 | BP29: =SUM(AZ29:BK29) -> 27.981019
A30: Cumulative CashFlow | B30: млн ₽ | D30: =D29 -> -1.212652 | E30: =D30+E29 -> -2.425304 | F30: =E30+F29 -> -3.6974809 | G30: =F30+G29 -> -4.8259623 | H30: =G30+H29 -> -6.9093918 | I30: =H30+I29 -> -7.7798749 | J30: =I30+J29 -> -8.3612993 | K30: =J30+K29 -> -7.6197457 | L30: =K30+L29 -> -6.5950761 | ... BK30: =BJ30+BK29 -> 100.73241 | BL30: =O30 -> -2.5910968 | BM30: =AA30 -> 20.25107 | BN30: =AM30 -> 45.936765 | BO30: =AY30 -> 72.751391 | BP30: =BK30 -> 100.73241
A32: КЛЮЧЕВЫЕ МЕТРИКИ
A33: Negative CF (min Cumulative CF) — пиковая потребность в финансировании | B33: млн ₽ | C33: =MIN(D30:BK30) -> -8.3612993
A34: Payback период (мес от старта до Cum CF >= 0) | B34: мес | C34: =MATCH(TRUE,INDEX(D30:BK30>=0,0),0) -> 15
A35: Cumulative CF к концу 2030 (NPV — без дисконтирования) | B35: млн ₽ | C35: =BK30 -> 100.73241
A36: NPV (Operating CF, дисконтированный WACC=26.3% годовых) | B36: млн ₽ | C36: =NPV((1+PnL!B10)^(1/12)-1,D29:BK29) -> 47.843436

Sheet Cost assumptions
A1: Cost assumptions - допущения по затратам (₽, помесячно за 5 лет)
A2: Все суммы в рублях. Параметры (жёлтый фон) можно менять, формулы (зелёный) пересчитаются автоматически. CoS - переменные затраты на инкрементальные заказы.
A4: 1. Входные параметры
A5: Параметр | B5: Значение | C5: Ед. | D5: Источник / обоснование
A6: Стоимость обработки доставки на заказ (логистика) | B6: 40 | C6: ₽/заказ | D6: Допущение
A7: Стоимость антифрод-проверки объявления | B7: 8 | C7: ₽/объявление | D7: Экспертно, диапазон 5-15 руб/объявление
A8: Доля incremental заказов в категории Животные | B8: 0.02 | C8: % | D8: Гипотеза: фичи дают +2% к транзакциям. Экспертно - линейный эффект от incremental engagement
A9: Доля incremental объявлений | B9: 0.05 | C9: % | D9: Гипотеза: рекомендации привлекают новых селлеров. Экспертно, +5% к объявлениям
A10: Marketing - % от Revenue (baseline AS IS) | B10: 0.05 | C10: % | D10: Бенчмарк marketing/revenue для classifieds. Avito ~5-7% (отчёт KASE Avito Group 2023)
A11: Marketing incremental - год 1 после запуска | B11: 4000000 | C11: ₽/год | D11: Промокампания + in-app коммуникации новых фич. Для Avito с её аудиторией 50M MAU не нужен большой external marketing - раскатка через персонализацию feed
A12: Marketing incremental - годы 2-5 | B12: 3000000 | C12: ₽/год | D12: Поддержка узнаваемости после ramp-up - минимальный бюджет 3 mR/год
A13: IT licenses - baseline направления | B13: 3000000 | C13: ₽/год | D13: Экспертно - стандартный стек ~3 mR/год для команды 30 чел
A14: IT licenses incremental (ML/CDN/storage) | B14: 1500000 | C14: ₽/год | D14: Экспертно
A15: IT оборудование на нового HC (единоразово) | B15: 100000 | C15: ₽/HC | D15: Ноут MacBook Pro/Workstation + лицензии (IDE, Notion). Экспертно - 100 тыс/чел с учетом того что оборудование уже есть, не всегда закупается новое
A16: G&A - % от Staff costs | B16: 0.05 | C16: % | D16: Юридическая поддержка + бухгалтерия + офис. Стандартное соотношение G&A/Staff в tech-компаниях 5-7%
A17: Baseline staff (направление Avito Animals AS IS) | B17: 25 | C17: FTE | D17: Текущая команда: разработка, аналитика, поддержка. Экспертно - 25 FTE для одного направления (среднего размера в Avito)
... A20: Темп индексации ставок ЗП | B20: 0.07 | C20: % г/г | D20: Экспертно
A25: 2. AS IS затраты (baseline направления Avito Животные)
A26: Статья | B26: Ед. | C26: Параметр | D26: 2026 | E26: 2026 | F26: 2026 | G26: 2026 | H26: 2026 | I26: 2026 | J26: 2026 | K26: 2026 | L26: 2026 | M26: 2026 | N26: 2026 | O26: 2026 | P26: 2027 | Q26: 2027 | R26: 2027 | S26: 2027 | T26: 2027 | U26: 2027 | V26: 2027 | W26: 2027 | X26: 2027 | Y26: 2027 | Z26: 2027 | AA26: 2027 | AB26: 2028 | AC26: 2028 | AD26: 2028 | AE26: 2028 | AF26: 2028 | AG26: 2028 | AH26: 2028 | AI26: 2028 | AJ26: 2028 | AK26: 2028 | AL26: 2028 | AM26: 2028 | AN26: 2029 | AO26: 2029 | AP26: 2029 | AQ26: 2029 | AR26: 2029 | AS26: 2029 | AT26: 2029 | AU26: 2029 | AV26: 2029 | AW26: 2029 | AX26: 2029 | AY26: 2029 | AZ26: 2030 | BA26: 2030 | BB26: 2030 | BC26: 2030 | BD26: 2030 | BE26: 2030 | BF26: 2030 | BG26: 2030 | BH26: 2030 | BI26: 2030 | BJ26: 2030 | BK26: 2030 | BL26: 2026 Total | BM26: 2027 Total | BN26: 2028 Total | BO26: 2029 Total | BP26: 2030 Total
D27: Jan | E27: Feb | F27: Mar | G27: Apr | H27: May | I27: Jun | J27: Jul | K27: Aug | L27: Sep | M27: Oct | N27: Nov | O27: Dec | P27: Jan | Q27: Feb | R27: Mar | S27: Apr | T27: May | U27: Jun | V27: Jul | W27: Aug | X27: Sep | Y27: Oct | Z27: Nov | AA27: Dec | AB27: Jan | AC27: Feb | AD27: Mar | AE27: Apr | AF27: May | AG27: Jun | AH27: Jul | AI27: Aug | AJ27: Sep | AK27: Oct | AL27: Nov | AM27: Dec | AN27: Jan | AO27: Feb | AP27: Mar | AQ27: Apr | AR27: May | AS27: Jun | AT27: Jul | AU27: Aug | AV27: Sep | AW27: Oct | AX27: Nov | AY27: Dec | AZ27: Jan | BA27: Feb | BB27: Mar | BC27: Apr | BD27: May | BE27: Jun | BF27: Jul | BG27: Aug | BH27: Sep | BI27: Oct | BJ27: Nov | BK27: Dec
A28: Revenue (AS IS, ссылка на Baseline TOP-down) - справочно | B28: ₽ | D28: ='Baseline TOP-down'!D24*1000 -> 20454545 | E28: ='Baseline TOP-down'!E24*1000 -> 41043017 | F28: ='Baseline TOP-down'!F24*1000 -> 32941905 | G28: ='Baseline TOP-down'!G24*1000 -> 33049748 | H28: ='Baseline TOP-down'!H24*1000 -> 33157944 | I28: ='Baseline TOP-down'!I24*1000 -> 33266495 | J28: ='Baseline TOP-down'!J24*1000 -> 33375400 | K28: ='Baseline TOP-down'!K24*1000 -> 33484663 | ... BK28: ='Baseline TOP-down'!BK24*1000 -> 47625365 | BL28: =SUM(D28:O28) -> 4.0936014e+08 | BM28: =SUM(P28:AA28) -> 4.1294306e+08 | BN28: =SUM(AB28:AM28) -> 4.2946078e+08 | BO28: =SUM(AN28:AY28) -> 4.4663921e+08 | BP28: =SUM(AZ28:BK28) -> 4.6450478e+08
A29: CoS baseline AS IS (% × Revenue) | B29: ₽ | C29: =B19 -> 0.02 | D29: =D28*$B$19 -> 409090.91 | E29: =E28*$B$19 -> 820860.33 | F29: =F28*$B$19 -> 658838.09 | G29: =G28*$B$19 -> 660994.96 | H29: =H28*$B$19 -> 663158.88 | I29: =I28*$B$19 -> 665329.89 | J29: =J28*$B$19 -> 667508.01 | K29: =K28*$B$19 -> 669693.26 | ... BK29: =BK28*$B$19 -> 952507.29 | BL29: =SUM(D29:O29) -> 8187202.9 | BM29: =SUM(P29:AA29) -> 8258861.1 | BN29: =SUM(AB29:AM29) -> 8589215.6 | BO29: =SUM(AN29:AY29) -> 8932784.2 | BP29: =SUM(AZ29:BK29) -> 9290095.6
A30: Staff baseline AS IS (FTE × Salary × индексация) | B30: ₽ | C30: =B17 -> 25 | D30: =$B$17*$B$18*(1+$B$20)^0 -> 7000000 | E30: =$B$17*$B$18*(1+$B$20)^0 -> 7000000 | F30: =$B$17*$B$18*(1+$B$20)^0 -> 7000000 | G30: =$B$17*$B$18*(1+$B$20)^0 -> 7000000 | H30: =$B$17*$B$18*(1+$B$20)^0 -> 7000000 | I30: =$B$17*$B$18*(1+$B$20)^0 -> 7000000 | J30: =$B$17*$B$18*(1+$B$20)^0 -> 7000000 | K30: =$B$17*$B$18*(1+$B$20)^0 -> 7000000 | ... O30: =$B$17*$B$18*(1+$B$20)^0 -> 7000000 | P30: =$B$17*$B$18*(1+$B$20)^1 -> 7490000 | Q30: =$B$17*$B$18*(1+$B$20)^1 -> 7490000 | R30: =$B$17*$B$18*(1+$B$20)^1 -> 7490000 | S30: =$B$17*$B$18*(1+$B$20)^1 -> 7490000 | T30: =$B$17*$B$18*(1+$B$20)^1 -> 7490000 | U30: =$B$17*$B$18*(1+$B$20)^1 -> 7490000 | V30: =$B$17*$B$18*(1+$B$20)^1 -> 7490000 | W30: =$B$17*$B$18*(1+$B$20)^1 -> 7490000 | ... AA30: =$B$17*$B$18*(1+$B$20)^1 -> 7490000 | AB30: =$B$17*$B$18*(1+$B$20)^2 -> 8014300 | AC30: =$B$17*$B$18*(1+$B$20)^2 -> 8014300 | AD30: =$B$17*$B$18*(1+$B$20)^2 -> 8014300 | AE30: =$B$17*$B$18*(1+$B$20)^2 -> 8014300 | AF30: =$B$17*$B$18*(1+$B$20)^2 -> 8014300 | AG30: =$B$17*$B$18*(1+$B$20)^2 -> 8014300 | AH30: =$B$17*$B$18*(1+$B$20)^2 -> 8014300 | AI30: =$B$17*$B$18*(1+$B$20)^2 -> 8014300 | ... AM30: =$B$17*$B$18*(1+$B$20)^2 -> 8014300 | AN30: =$B$17*$B$18*(1+$B$20)^3 -> 8575301 | AO30: =$B$17*$B$18*(1+$B$20)^3 -> 8575301 | AP30: =$B$17*$B$18*(1+$B$20)^3 -> 8575301 | AQ30: =$B$17*$B$18*(1+$B$20)^3 -> 8575301 | AR30: =$B$17*$B$18*(1+$B$20)^3 -> 8575301 | AS30: =$B$17*$B$18*(1+$B$20)^3 -> 8575301 | AT30: =$B$17*$B$18*(1+$B$20)^3 -> 8575301 | AU30: =$B$17*$B$18*(1+$B$20)^3 -> 8575301 | ... AY30: =$B$17*$B$18*(1+$B$20)^3 -> 8575301 | AZ30: =$B$17*$B$18*(1+$B$20)^4 -> 9175572.1 | BA30: =$B$17*$B$18*(1+$B$20)^4 -> 9175572.1 | BB30: =$B$17*$B$18*(1+$B$20)^4 -> 9175572.1 | BC30: =$B$17*$B$18*(1+$B$20)^4 -> 9175572.1 | BD30: =$B$17*$B$18*(1+$B$20)^4 -> 9175572.1 | BE30: =$B$17*$B$18*(1+$B$20)^4 -> 9175572.1 | BF30: =$B$17*$B$18*(1+$B$20)^4 -> 9175572.1 | BG30: =$B$17*$B$18*(1+$B$20)^4 -> 9175572.1 | ... BK30: =$B$17*$B$18*(1+$B$20)^4 -> 9175572.1 | BL30: =SUM(D30:O30) -> 84000000 | BM30: =SUM(P30:AA30) -> 89880000 | BN30: =SUM(AB30:AM30) -> 96171600 | BO30: =SUM(AN30:AY30) -> 102903612 | BP30: =SUM(AZ30:BK30) -> 1.1010686e+08
A31: Marketing baseline AS IS (% × Revenue) | B31: ₽ | C31: =B10 -> 0.05 | D31: =D28*$B$10 -> 1022727.3 | E31: =E28*$B$10 -> 2052150.8 | F31: =F28*$B$10 -> 1647095.2 | G31: =G28*$B$10 -> 1652487.4 | H31: =H28*$B$10 -> 1657897.2 | I31: =I28*$B$10 -> 1663324.7 | J31: =J28*$B$10 -> 1668770 | K31: =K28*$B$10 -> 1674233.1 | ... BK31: =BK28*$B$10 -> 2381268.2 | BL31: =SUM(D31:O31) -> 20468007 | BM31: =SUM(P31:AA31) -> 20647153 | BN31: =SUM(AB31:AM31) -> 21473039 | BO31: =SUM(AN31:AY31) -> 22331960 | BP31: =SUM(AZ31:BK31) -> 23225239
A32: IT baseline AS IS (равномерно по месяцам) | B32: ₽ | C32: =B13 -> 3000000 | D32: =$B$13/12 -> 250000 | E32: =$B$13/12 -> 250000 | F32: =$B$13/12 -> 250000 | G32: =$B$13/12 -> 250000 | H32: =$B$13/12 -> 250000 | I32: =$B$13/12 -> 250000 | J32: =$B$13/12 -> 250000 | K32: =$B$13/12 -> 250000 | ... BK32: =$B$13/12 -> 250000 | BL32: =SUM(D32:O32) -> 3000000 | BM32: =SUM(P32:AA32) -> 3000000 | BN32: =SUM(AB32:AM32) -> 3000000 | BO32: =SUM(AN32:AY32) -> 3000000 | BP32: =SUM(AZ32:BK32) -> 3000000
A33: G&A baseline AS IS (% × Staff baseline) | B33: ₽ | C33: =B16 -> 0.05 | D33: =D30*$B$16 -> 350000 | E33: =E30*$B$16 -> 350000 | F33: =F30*$B$16 -> 350000 | G33: =G30*$B$16 -> 350000 | H33: =H30*$B$16 -> 350000 | I33: =I30*$B$16 -> 350000 | J33: =J30*$B$16 -> 350000 | K33: =K30*$B$16 -> 350000 | ... BK33: =BK30*$B$16 -> 458778.6 | BL33: =SUM(D33:O33) -> 4200000 | BM33: =SUM(P33:AA33) -> 4494000 | BN33: =SUM(AB33:AM33) -> 4808580 | BO33: =SUM(AN33:AY33) -> 5145180.6 | BP33: =SUM(AZ33:BK33) -> 5505343.2
A34: Σ OPEX AS IS (без CoS, до EBITDA) | D34: =SUM(D29:D33) -> 9031818.2 | E34: =SUM(E29:E33) -> 10473011 | F34: =SUM(F29:F33) -> 9905933.3 | G34: =SUM(G29:G33) -> 9913482.3 | H34: =SUM(H29:H33) -> 9921056.1 | I34: =SUM(I29:I33) -> 9928654.6 | J34: =SUM(J29:J33) -> 9936278 | K34: =SUM(K29:K33) -> 9943926.4 | ... BK34: =SUM(BK29:BK33) -> 13218126 | BL34: =SUM(D34:O34) -> 1.1985521e+08 | BM34: =SUM(P34:AA34) -> 1.2628001e+08 | BN34: =SUM(AB34:AM34) -> 1.3404243e+08 | BO34: =SUM(AN34:AY34) -> 1.4231354e+08 | BP34: =SUM(AZ34:BK34) -> 1.5112754e+08
A36: 3. Increment затраты (от нашей инициативы: 3 волны)
A37: Статья - Revenue INCR = 0 в мес 1-7 (период Discovery+Dev Wave 1, до Launch в мес 8). | B37: Ед. | C37: Параметр | D37: 2026 | E37: 2026 | F37: 2026 | G37: 2026 | H37: 2026 | I37: 2026 | J37: 2026 | K37: 2026 | L37: 2026 | M37: 2026 | N37: 2026 | O37: 2026 | P37: 2027 | Q37: 2027 | R37: 2027 | S37: 2027 | T37: 2027 | U37: 2027 | V37: 2027 | W37: 2027 | X37: 2027 | Y37: 2027 | Z37: 2027 | AA37: 2027 | AB37: 2028 | AC37: 2028 | AD37: 2028 | AE37: 2028 | AF37: 2028 | AG37: 2028 | AH37: 2028 | AI37: 2028 | AJ37: 2028 | AK37: 2028 | AL37: 2028 | AM37: 2028 | AN37: 2029 | AO37: 2029 | AP37: 2029 | AQ37: 2029 | AR37: 2029 | AS37: 2029 | AT37: 2029 | AU37: 2029 | AV37: 2029 | AW37: 2029 | AX37: 2029 | AY37: 2029 | AZ37: 2030 | BA37: 2030 | BB37: 2030 | BC37: 2030 | BD37: 2030 | BE37: 2030 | BF37: 2030 | BG37: 2030 | BH37: 2030 | BI37: 2030 | BJ37: 2030 | BK37: 2030 | BL37: 2026 Total | BM37: 2027 Total | BN37: 2028 Total | BO37: 2029 Total | BP37: 2030 Total
D38: Jan | E38: Feb | F38: Mar | G38: Apr | H38: May | I38: Jun | J38: Jul | K38: Aug | L38: Sep | M38: Oct | N38: Nov | O38: Dec | P38: Jan | Q38: Feb | R38: Mar | S38: Apr | T38: May | U38: Jun | V38: Jul | W38: Aug | X38: Sep | Y38: Oct | Z38: Nov | AA38: Dec | AB38: Jan | AC38: Feb | AD38: Mar | AE38: Apr | AF38: May | AG38: Jun | AH38: Jul | AI38: Aug | AJ38: Sep | AK38: Oct | AL38: Nov | AM38: Dec | AN38: Jan | AO38: Feb | AP38: Mar | AQ38: Apr | AR38: May | AS38: Jun | AT38: Jul | AU38: Aug | AV38: Sep | AW38: Oct | AX38: Nov | AY38: Dec | AZ38: Jan | BA38: Feb | BB38: Mar | BC38: Apr | BD38: May | BE38: Jun | BF38: Jul | BG38: Aug | BH38: Sep | BI38: Oct | BJ38: Nov | BK38: Dec
